Workbook

Sheet Leaderboard
B2: Leaderboard | H2: Stats
B3: Pos. | C3: Golfer | D3: Points | E3: Behind | F3: Weeks Counted | H3: Golfer | I3: Match Wins | J3: Match Losses | K3: Match Ties | L3: Blank Weeks | M3: Avg. Weekly Points | N3: Eagles | O3: Avg. Score | P3: Lowest Score | Q3: Avg. Putts | R3: Lowest Putts
B4: 1 | C4: Joey | D4: =SUMIF('Weekly Point Data'!$E:$E, C4, 'Weekly Point Data'!$U:$U) -> 80 | E4: =D4-$D$4 -> 0 | F4: =COUNTIFS('Weekly Point Data'!F:F,"Confirmed",'Weekly Point Data'!E:E,C4) -> 5 | H4: =C4 -> Joey | I4: =COUNTIFS('Weekly Point Data'!L:L,"Won",'Weekly Point Data'!E:E,H4) -> 2 | J4: =COUNTIFS('Weekly Point Data'!L:L,"Lost",'Weekly Point Data'!E:E,H4) -> 2 | K4: =COUNTIFS('Weekly Point Data'!L:L,"Tied",'Weekly Point Data'!E:E,H4) -> 1 | L4: =COUNTIFS('Weekly Point Data'!F:F,"No",'Weekly Point Data'!E:E,H4) -> 1 | M4: =AVERAGEIFS('Weekly Point Data'!U:U,'Weekly Point Data'!E:E,H4,'Weekly Point Data'!U:U,">0") -> 16 | N4: - | O4: =AVERAGEIFS('Weekly Point Data'!M:M,'Weekly Point Data'!E:E,H4) -> 42.4 | P4: =MINIFS('Weekly Point Data'!M:M,'Weekly Point Data'!E:E,H4) -> 40 | Q4: =AVERAGEIFS('Weekly Point Data'!N:N,'Weekly Point Data'!E:E,H4) -> 17.2 | R4: =MINIFS('Weekly Point Data'!N:N,'Weekly Point Data'!E:E,H4) -> 15
B5: 2 | C5: Bryan | D5: =SUMIF('Weekly Point Data'!$E:$E, C5, 'Weekly Point Data'!$U:$U) -> 76 | E5: =D5-$D$4 -> -4 | F5: =COUNTIFS('Weekly Point Data'!F:F,"Confirmed",'Weekly Point Data'!E:E,C5) -> 5 | H5: =C5 -> Bryan | I5: =COUNTIFS('Weekly Point Data'!L:L,"Won",'Weekly Point Data'!E:E,H5) -> 1 | J5: =COUNTIFS('Weekly Point Data'!L:L,"Lost",'Weekly Point Data'!E:E,H5) -> 2 | K5: =COUNTIFS('Weekly Point Data'!L:L,"Tied",'Weekly Point Data'!E:E,H5) -> 2 | L5: =COUNTIFS('Weekly Point Data'!F:F,"No",'Weekly Point Data'!E:E,H5) -> 1 | M5: =AVERAGEIFS('Weekly Point Data'!U:U,'Weekly Point Data'!E:E,H5,'Weekly Point Data'!U:U,">0") -> 15.2 | N5: - | O5: =AVERAGEIFS('Weekly Point Data'!M:M,'Weekly Point Data'!E:E,H5) -> 42.4 | P5: =MINIFS('Weekly Point Data'!M:M,'Weekly Point Data'!E:E,H5) -> 39 | Q5: =AVERAGEIFS('Weekly Point Data'!N:N,'Weekly Point Data'!E:E,H5) -> 17.6 | R5: =MINIFS('Weekly Point Data'!N:N,'Weekly Point Data'!E:E,H5) -> 16
B6: 3 | C6: Bird | D6: =SUMIF('Weekly Point Data'!$E:$E, C6, 'Weekly Point Data'!$U:$U) -> 73 | E6: =D6-$D$4 -> -7 | F6: =COUNTIFS('Weekly Point Data'!F:F,"Confirmed",'Weekly Point Data'!E:E,C6) -> 5 | H6: =C6 -> Bird | I6: =COUNTIFS('Weekly Point Data'!L:L,"Won",'Weekly Point Data'!E:E,H6) -> 4 | J6: =COUNTIFS('Weekly Point Data'!L:L,"Lost",'Weekly Point Data'!E:E,H6) -> 0 | K6: =COUNTIFS('Weekly Point Data'!L:L,"Tied",'Weekly Point Data'!E:E,H6) -> 1 | L6: =COUNTIFS('Weekly Point Data'!F:F,"No",'Weekly Point Data'!E:E,H6) -> 1 | M6: =AVERAGEIFS('Weekly Point Data'!U:U,'Weekly Point Data'!E:E,H6,'Weekly Point Data'!U:U,">0") -> 14.6 | N6: - | O6: =AVERAGEIFS('Weekly Point Data'!M:M,'Weekly Point Data'!E:E,H6) -> 44.2 | P6: =MINIFS('Weekly Point Data'!M:M,'Weekly Point Data'!E:E,H6) -> 42 | Q6: =AVERAGEIFS('Weekly Point Data'!N:N,'Weekly Point Data'!E:E,H6) -> 19.4 | R6: =MINIFS('Weekly Point Data'!N:N,'Weekly Point Data'!E:E,H6) -> 18
B7: 4 | C7: Zach | D7: =SUMIF('Weekly Point Data'!$E:$E, C7, 'Weekly Point Data'!$U:$U) -> 72 | E7: =D7-$D$4 -> -8 | F7: =COUNTIFS('Weekly Point Data'!F:F,"Confirmed",'Weekly Point Data'!E:E,C7) -> 6 | H7: =C7 -> Zach | I7: =COUNTIFS('Weekly Point Data'!L:L,"Won",'Weekly Point Data'!E:E,H7) -> 1 | J7: =COUNTIFS('Weekly Point Data'!L:L,"Lost",'Weekly Point Data'!E:E,H7) -> 3 | K7: =COUNTIFS('Weekly Point Data'!L:L,"Tied",'Weekly Point Data'!E:E,H7) -> 2 | L7: =COUNTIFS('Weekly Point Data'!F:F,"No",'Weekly Point Data'!E:E,H7) -> 0 | M7: =AVERAGEIFS('Weekly Point Data'!U:U,'Weekly Point Data'!E:E,H7,'Weekly Point Data'!U:U,">0") -> 12 | N7: 1 | O7: =AVERAGEIFS('Weekly Point Data'!M:M,'Weekly Point Data'!E:E,H7) -> 47.5 | P7: =MINIFS('Weekly Point Data'!M:M,'Weekly Point Data'!E:E,H7) -> 40 | Q7: =AVERAGEIFS('Weekly Point Data'!N:N,'Weekly Point Data'!E:E,H7) -> 16.666667 | R7: =MINIFS('Weekly Point Data'!N:N,'Weekly Point Data'!E:E,H7) -> 13
B8: 5 | C8: Stefan | D8: =SUMIF('Weekly Point Data'!$E:$E, C8, 'Weekly Point Data'!$U:$U) -> 66 | E8: =D8-$D$4 -> -14 | F8: =COUNTIFS('Weekly Point Data'!F:F,"Confirmed",'Weekly Point Data'!E:E,C8) -> 4 | H8: =C8 -> Stefan | I8: =COUNTIFS('Weekly Point Data'!L:L,"Won",'Weekly Point Data'!E:E,H8) -> 2 | J8: =COUNTIFS('Weekly Point Data'!L:L,"Lost",'Weekly Point Data'!E:E,H8) -> 1 | K8: =COUNTIFS('Weekly Point Data'!L:L,"Tied",'Weekly Point Data'!E:E,H8) -> 1 | L8: =COUNTIFS('Weekly Point Data'!F:F,"No",'Weekly Point Data'!E:E,H8) -> 2 | M8: =AVERAGEIFS('Weekly Point Data'!U:U,'Weekly Point Data'!E:E,H8,'Weekly Point Data'!U:U,">0") -> 16.5 | N8: - | O8: =AVERAGEIFS('Weekly Point Data'!M:M,'Weekly Point Data'!E:E,H8) -> 42.25 | P8: =MINIFS('Weekly Point Data'!M:M,'Weekly Point Data'!E:E,H8) -> 41 | Q8: =AVERAGEIFS('Weekly Point Data'!N:N,'Weekly Point Data'!E:E,H8) -> 16.5 | R8: =MINIFS('Weekly Point Data'!N:N,'Weekly Point Data'!E:E,H8) -> 16
B9: 6 | C9: GT | D9: =SUMIF('Weekly Point Data'!$E:$E, C9, 'Weekly Point Data'!$U:$U) -> 63 | E9: =D9-$D$4 -> -17 | F9: =COUNTIFS('Weekly Point Data'!F:F,"Confirmed",'Weekly Point Data'!E:E,C9) -> 5 | H9: =C9 -> GT | I9: =COUNTIFS('Weekly Point Data'!L:L,"Won",'Weekly Point Data'!E:E,H9) -> 2 | J9: =COUNTIFS('Weekly Point Data'!L:L,"Lost",'Weekly Point Data'!E:E,H9) -> 3 | K9: =COUNTIFS('Weekly Point Data'!L:L,"Tied",'Weekly Point Data'!E:E,H9) -> 0 | L9: =COUNTIFS('Weekly Point Data'!F:F,"No",'Weekly Point Data'!E:E,H9) -> 1 | M9: =AVERAGEIFS('Weekly Point Data'!U:U,'Weekly Point Data'!E:E,H9,'Weekly Point Data'!U:U,">0") -> 12.6 | N9: - | O9: =AVERAGEIFS('Weekly Point Data'!M:M,'Weekly Point Data'!E:E,H9) -> 44 | P9: =MINIFS('Weekly Point Data'!M:M,'Weekly Point Data'!E:E,H9) -> 40 | Q9: =AVERAGEIFS('Weekly Point Data'!N:N,'Weekly Point Data'!E:E,H9) -> 17.4 | R9: =MINIFS('Weekly Point Data'!N:N,'Weekly Point Data'!E:E,H9) -> 15
B10: 7 | C10: Joe | D10: =SUMIF('Weekly Point Data'!$E:$E, C10, 'Weekly Point Data'!$U:$U) -> 61 | E10: =D10-$D$4 -> -19 | F10: =COUNTIFS('Weekly Point Data'!F:F,"Confirmed",'Weekly Point Data'!E:E,C10) -> 5 | H10: =C10 -> Joe | I10: =COUNTIFS('Weekly Point Data'!L:L,"Won",'Weekly Point Data'!E:E,H10) -> 1 | J10: =COUNTIFS('Weekly Point Data'!L:L,"Lost",'Weekly Point Data'!E:E,H10) -> 2 | K10: =COUNTIFS('Weekly Point Data'!L:L,"Tied",'Weekly Point Data'!E:E,H10) -> 2 | L10: =COUNTIFS('Weekly Point Data'!F:F,"No",'Weekly Point Data'!E:E,H10) -> 1 | M10: =AVERAGEIFS('Weekly Point Data'!U:U,'Weekly Point Data'!E:E,H10,'Weekly Point Data'!U:U,">0") -> 12.2 | N10: - | O10: =AVERAGEIFS('Weekly Point Data'!M:M,'Weekly Point Data'!E:E,H10) -> 47 | P10: =MINIFS('Weekly Point Data'!M:M,'Weekly Point Data'!E:E,H10) -> 42 | Q10: =AVERAGEIFS('Weekly Point Data'!N:N,'Weekly Point Data'!E:E,H10) -> 16.8 | R10: =MINIFS('Weekly Point Data'!N:N,'Weekly Point Data'!E:E,H10) -> 13
B11: 8 | C11: Hunter | D11: =SUMIF('Weekly Point Data'!$E:$E, C11, 'Weekly Point Data'!$U:$U) -> 25 | E11: =D11-$D$4 -> -55 | F11: =COUNTIFS('Weekly Point Data'!F:F,"Confirmed",'Weekly Point Data'!E:E,C11) -> 4 | H11: =C11 -> Hunter | I11: =COUNTIFS('Weekly Point Data'!L:L,"Won",'Weekly Point Data'!E:E,H11) -> 1 | J11: =COUNTIFS('Weekly Point Data'!L:L,"Lost",'Weekly Point Data'!E:E,H11) -> 3 | K11: =COUNTIFS('Weekly Point Data'!L:L,"Tied",'Weekly Point Data'!E:E,H11) -> 0 | L11: =COUNTIFS('Weekly Point Data'!F:F,"No",'Weekly Point Data'!E:E,H11) -> 2 | M11: =AVERAGEIFS('Weekly Point Data'!U:U,'Weekly Point Data'!E:E,H11,'Weekly Point Data'!U:U,">0") -> 6.25 | N11: - | O11: =AVERAGEIFS('Weekly Point Data'!M:M,'Weekly Point Data'!E:E,H11) -> 55.25 | P11: =MINIFS('Weekly Point Data'!M:M,'Weekly Point Data'!E:E,H11) -> 54 | Q11: =AVERAGEIFS('Weekly Point Data'!N:N,'Weekly Point Data'!E:E,H11) -> 17.25 | R11: =MINIFS('Weekly Point Data'!N:N,'Weekly Point Data'!E:E,H11) -> 14
B12: 9 | C12: John | D12: =SUMIF('Weekly Point Data'!$E:$E, C12, 'Weekly Point Data'!$U:$U) -> 20 | E12: =D12-$D$4 -> -60 | F12: =COUNTIFS('Weekly Point Data'!F:F,"Confirmed",'Weekly Point Data'!E:E,C12) -> 4 | H12: =C12 -> John | I12: =COUNTIFS('Weekly Point Data'!L:L,"Won",'Weekly Point Data'!E:E,H12) -> 0 | J12: =COUNTIFS('Weekly Point Data'!L:L,"Lost",'Weekly Point Data'!E:E,H12) -> 3 | K12: =COUNTIFS('Weekly Point Data'!L:L,"Tied",'Weekly Point Data'!E:E,H12) -> 1 | L12: =COUNTIFS('Weekly Point Data'!F:F,"No",'Weekly Point Data'!E:E,H12) -> 2 | M12: =AVERAGEIFS('Weekly Point Data'!U:U,'Weekly Point Data'!E:E,H12,'Weekly Point Data'!U:U,">0") -> 5 | N12: - | O12: =AVERAGEIFS('Weekly Point Data'!M:M,'Weekly Point Data'!E:E,H12) -> 57.75 | P12: =MINIFS('Weekly Point Data'!M:M,'Weekly Point Data'!E:E,H12) -> 54 | Q12: =AVERAGEIFS('Weekly Point Data'!N:N,'Weekly Point Data'!E:E,H12) -> 13.5 | R12: =MINIFS('Weekly Point Data'!N:N,'Weekly Point Data'!E:E,H12) -> 0
B13: 10 | C13: Jared | D13: =SUMIF('Weekly Point Data'!$E:$E, C13, 'Weekly Point Data'!$U:$U) -> 16 | E13: =D13-$D$4 -> -64 | F13: =COUNTIFS('Weekly Point Data'!F:F,"Confirmed",'Weekly Point Data'!E:E,C13) -> 2 | H13: =C13 -> Jared | I13: =COUNTIFS('Weekly Point Data'!L:L,"Won",'Weekly Point Data'!E:E,H13) -> 0 | J13: =COUNTIFS('Weekly Point Data'!L:L,"Lost",'Weekly Point Data'!E:E,H13) -> 0 | K13: =COUNTIFS('Weekly Point Data'!L:L,"Tied",'Weekly Point Data'!E:E,H13) -> 2 | L13: =COUNTIFS('Weekly Point Data'!F:F,"No",'Weekly Point Data'!E:E,H13) -> 4 | M13: =AVERAGEIFS('Weekly Point Data'!U:U,'Weekly Point Data'!E:E,H13,'Weekly Point Data'!U:U,">0") -> 8 | N13: - | O13: =AVERAGEIFS('Weekly Point Data'!M:M,'Weekly Point Data'!E:E,H13) -> 55 | P13: =MINIFS('Weekly Point Data'!M:M,'Weekly Point Data'!E:E,H13) -> 52 | Q13: =AVERAGEIFS('Weekly Point Data'!N:N,'Weekly Point Data'!E:E,H13) -> 19 | R13: =MINIFS('Weekly Point Data'!N:N,'Weekly Point Data'!E:E,H13) -> 18
B14: 11 | C14: Brandt | D14: =SUMIF('Weekly Point Data'!$E:$E, C14, 'Weekly Point Data'!$U:$U) -> 13 | E14: =D14-$D$4 -> -67 | F14: =COUNTIFS('Weekly Point Data'!F:F,"Confirmed",'Weekly Point Data'!E:E,C14) -> 2 | H14: =C14 -> Brandt | I14: =COUNTIFS('Weekly Point Data'!L:L,"Won",'Weekly Point Data'!E:E,H14) -> 0 | J14: =COUNTIFS('Weekly Point Data'!L:L,"Lost",'Weekly Point Data'!E:E,H14) -> 1 | K14: =COUNTIFS('Weekly Point Data'!L:L,"Tied",'Weekly Point Data'!E:E,H14) -> 1 | L14: =COUNTIFS('Weekly Point Data'!F:F,"No",'Weekly Point Data'!E:E,H14) -> 4 | M14: =AVERAGEIFS('Weekly Point Data'!U:U,'Weekly Point Data'!E:E,H14,'Weekly Point Data'!U:U,">0") -> 6.5 | N14: - | O14: =AVERAGEIFS('Weekly Point Data'!M:M,'Weekly Point Data'!E:E,H14) -> 50 | P14: =MINIFS('Weekly Point Data'!M:M,'Weekly Point Data'!E:E,H14) -> 49 | Q14: =AVERAGEIFS('Weekly Point Data'!N:N,'Weekly Point Data'!E:E,H14) -> 8 | R14: =MINIFS('Weekly Point Data'!N:N,'Weekly Point Data'!E:E,H14) -> 0

Sheet Weekly Point Data
A1: Weekly Details | F1: Match Details | P1: Point Details | U1: Total
A2: Week | B2: Date | C2: Course | D2: Nine | E2: Golfer | F2: Showed | G2: Beers | H2: Partner | I2: Op #1 | J2: Op #2 | K2: HCP | L2: Match Result | M2: Gross Score | N2: Putts | O2: Net Score | P2: Showing Up Points | Q2: Match Points | R2: Gross Points | S2: Net Points | T2: Putt Points | U2: Points
A3: W07 | B3: 46195 | C3: Broken Tee | D3: Front | E3: Bird | F3: unk | G3: - | L3: n/a | O3: =M3-ROUNDUP(K3/2,0) -> 0 | P3: =IFS(F3="Yes",3,F3="No",0,F3="Confirmed",3,F3="unk",0) -> 0 | Q3: =IFS(L3="Tied",2,L3="Won",5,L3="Lost",0,L3="n/a",0) -> 0 | U3: =SUM(P3:T3) -> 0
A4: W07 | B4: 46195 | C4: Broken Tee | D4: Front | E4: Brandt | F4: unk | G4: - | L4: n/a | O4: =M4-ROUNDUP(K4/2,0) -> 0 | P4: =IFS(F4="Yes",3,F4="No",0,F4="Confirmed",3,F4="unk",0) -> 0 | Q4: =IFS(L4="Tied",2,L4="Won",5,L4="Lost",0,L4="n/a",0) -> 0 | U4: =SUM(P4:T4) -> 0
A5: W07 | B5: 46195 | C5: Broken Tee | D5: Front | E5: Bryan | F5: unk | G5: - | L5: n/a | O5: =M5-ROUNDUP(K5/2,0) -> 0 | P5: =IFS(F5="Yes",3,F5="No",0,F5="Confirmed",3,F5="unk",0) -> 0 | Q5: =IFS(L5="Tied",2,L5="Won",5,L5="Lost",0,L5="n/a",0) -> 0 | U5: =SUM(P5:T5) -> 0
A6: W07 | B6: 46195 | C6: Broken Tee | D6: Front | E6: GT | F6: unk | G6: - | L6: n/a | O6: =M6-ROUNDUP(K6/2,0) -> 0 | P6: =IFS(F6="Yes",3,F6="No",0,F6="Confirmed",3,F6="unk",0) -> 0 | Q6: =IFS(L6="Tied",2,L6="Won",5,L6="Lost",0,L6="n/a",0) -> 0 | U6: =SUM(P6:T6) -> 0
A7: W07 | B7: 46195 | C7: Broken Tee | D7: Front | E7: Hunter | F7: unk | G7: - | L7: n/a | O7: =M7-ROUNDUP(K7/2,0) -> 0 | P7: =IFS(F7="Yes",3,F7="No",0,F7="Confirmed",3,F7="unk",0) -> 0 | Q7: =IFS(L7="Tied",2,L7="Won",5,L7="Lost",0,L7="n/a",0) -> 0 | U7: =SUM(P7:T7) -> 0
A8: W07 | B8: 46195 | C8: Broken Tee | D8: Front | E8: Jared | F8: unk | G8: - | L8: n/a | O8: =M8-ROUNDUP(K8/2,0) -> 0 | P8: =IFS(F8="Yes",3,F8="No",0,F8="Confirmed",3,F8="unk",0) -> 0 | Q8: =IFS(L8="Tied",2,L8="Won",5,L8="Lost",0,L8="n/a",0) -> 0 | U8: =SUM(P8:T8) -> 0
A9: W07 | B9: 46195 | C9: Broken Tee | D9: Front | E9: Joe | F9: unk | G9: - | L9: n/a | O9: =M9-ROUNDUP(K9/2,0) -> 0 | P9: =IFS(F9="Yes",3,F9="No",0,F9="Confirmed",3,F9="unk",0) -> 0 | Q9: =IFS(L9="Tied",2,L9="Won",5,L9="Lost",0,L9="n/a",0) -> 0 | U9: =SUM(P9:T9) -> 0
A10: W07 | B10: 46195 | C10: Broken Tee | D10: Front | E10: Joey | F10: unk | G10: - | L10: n/a | O10: =M10-ROUNDUP(K10/2,0) -> 0 | P10: =IFS(F10="Yes",3,F10="No",0,F10="Confirmed",3,F10="unk",0) -> 0 | Q10: =IFS(L10="Tied",2,L10="Won",5,L10="Lost",0,L10="n/a",0) -> 0 | U10: =SUM(P10:T10) -> 0
A11: W07 | B11: 46195 | C11: Broken Tee | D11: Front | E11: John | F11: unk | G11: - | L11: n/a | O11: =M11-ROUNDUP(K11/2,0) -> 0 | P11: =IFS(F11="Yes",3,F11="No",0,F11="Confirmed",3,F11="unk",0) -> 0 | Q11: =IFS(L11="Tied",2,L11="Won",5,L11="Lost",0,L11="n/a",0) -> 0 | U11: =SUM(P11:T11) -> 0
A12: W07 | B12: 46195 | C12: Broken Tee | D12: Front | E12: Stefan | F12: unk | G12: - | L12: n/a | O12: =M12-ROUNDUP(K12/2,0) -> 0 | P12: =IFS(F12="Yes",3,F12="No",0,F12="Confirmed",3,F12="unk",0) -> 0 | Q12: =IFS(L12="Tied",2,L12="Won",5,L12="Lost",0,L12="n/a",0) -> 0 | U12: =SUM(P12:T12) -> 0
A13: W07 | B13: 46195 | C13: Broken Tee | D13: Front | E13: Zach | F13: unk | G13: - | L13: n/a | O13: =M13-ROUNDUP(K13/2,0) -> 0 | P13: =IFS(F13="Yes",3,F13="No",0,F13="Confirmed",3,F13="unk",0) -> 0 | Q13: =IFS(L13="Tied",2,L13="Won",5,L13="Lost",0,L13="n/a",0) -> 0 | U13: =SUM(P13:T13) -> 0
A14: W06 | B14: 46189 | C14: Broken Tee | D14: Front | E14: Bird | F14: Confirmed | G14: - | H14: Zach | I14: Brandt | J14: Joe | K14: 15.8 | L14: Tied | M14: 47 | N14: 19 | O14: =M14-ROUNDUP(K14/2,0) -> 39 | P14: =IFS(F14="Yes",3,F14="No",0,F14="Confirmed",3,F14="unk",0) -> 3 | Q14: =IFS(L14="Tied",2,L14="Won",5,L14="Lost",0,L14="n/a",0) -> 2 | R14: 1 | S14: 2 | T14: 1 | U14: =SUM(P14:T14) -> 9
A15: W06 | B15: 46189 | C15: Broken Tee | D15: Front | E15: Brandt | F15: Confirmed | G15: - | H15: Joe | I15: Bird | J15: Zach | K15: 10 | L15: Tied | M15: 49 | N15: 0 | O15: =M15-ROUNDUP(K15/2,0) -> 44 | P15: =IFS(F15="Yes",3,F15="No",0,F15="Confirmed",3,F15="unk",0) -> 3 | Q15: =IFS(L15="Tied",2,L15="Won",5,L15="Lost",0,L15="n/a",0) -> 2 | R15: 0 | S15: 1 | T15: 0 | U15: =SUM(P15:T15) -> 6
A16: W06 | B16: 46189 | C16: Broken Tee | D16: Front | E16: Bryan | F16: No | G16: - | H16: - | I16: - | J16: - | K16: - | L16: n/a | M16: - | N16: - | O16: - | P16: 0 | Q16: 0 | R16: 0 | S16: 0 | T16: 0 | U16: 0
A17: W06 | B17: 46189 | C17: Broken Tee | D17: Front | E17: GT | F17: Confirmed | G17: - | H17: John | I17: Joey | J17: Stefan | K17: 13.8 | L17: Lost | M17: 44 | N17: 20 | O17: =M17-ROUNDUP(K17/2,0) -> 37 | P17: =IFS(F17="Yes",3,F17="No",0,F17="Confirmed",3,F17="unk",0) -> 3 | Q17: =IFS(L17="Tied",2,L17="Won",5,L17="Lost",0,L17="n/a",0) -> 0 | R17: 3 | S17: 3 | T17: 0 | U17: =SUM(P17:T17) -> 9
A18: W06 | B18: 46189 | C18: Broken Tee | D18: Front | E18: Hunter | F18: No | G18: - | H18: - | I18: - | J18: - | K18: - | L18: n/a | M18: - | N18: - | O18: - | P18: 0 | Q18: 0 | R18: 0 | S18: 0 | T18: 0 | U18: 0
A19: W06 | B19: 46189 | C19: Broken Tee | D19: Front | E19: Jared | F19: No | G19: - | H19: - | I19: - | J19: - | K19: - | L19: n/a | M19: - | N19: - | O19: - | P19: 0 | Q19: 0 | R19: 0 | S19: 0 | T19: 0 | U19: 0
A20: W06 | B20: 46189 | C20: Broken Tee | D20: Front | E20: Joe | F20: Confirmed | G20: - | H20: Brandt | I20: Bird | J20: Zach | K20: 18.5 | L20: Tied | M20: 47 | N20: 17 | O20: =M20-ROUNDUP(K20/2,0) -> 37 | P20: =IFS(F20="Yes",3,F20="No",0,F20="Confirmed",3,F20="unk",0) -> 3 | Q20: =IFS(L20="Tied",2,L20="Won",5,L20="Lost",0,L20="n/a",0) -> 2 | R20: 1 | S20: 3 | T20: 2 | U20: =SUM(P20:T20) -> 11
A21: W06 | B21: 46189 | C21: Broken Tee | D21: Front | E21: Joey | F21: Confirmed | G21: - | H21: Stefan | I21: John | J21: GT | K21: 11 | L21: Won | M21: 40 | N21: 15 | O21: =M21-ROUNDUP(K21/2,0) -> 34 | P21: =IFS(F21="Yes",3,F21="No",0,F21="Confirmed",3,F21="unk",0) -> 3 | Q21: =IFS(L21="Tied",2,L21="Won",5,L21="Lost",0,L21="n/a",0) -> 5 | R21: 6 | S21: 5 | T21: 4 | U21: =SUM(P21:T21) -> 23
A22: W06 | B22: 46189 | C22: Broken Tee | D22: Front | E22: John | F22: Confirmed | G22: - | H22: GT | I22: Joey | J22: Stefan | K22: 31.7 | L22: Lost | M22: 63 | N22: 0 | O22: =M22-ROUNDUP(K22/2,0) -> 47 | P22: =IFS(F22="Yes",3,F22="No",0,F22="Confirmed",3,F22="unk",0) -> 3 | Q22: =IFS(L22="Tied",2,L22="Won",5,L22="Lost",0,L22="n/a",0) -> 0 | R22: 0 | S22: 0 | T22: 0 | U22: =SUM(P22:T22) -> 3
A23: W06 | B23: 46189 | C23: Broken Tee | D23: Front | E23: Stefan | F23: Confirmed | G23: - | H23: Joey | I23: John | J23: GT | K23: 11.5 | L23: Won | M23: 43 | N23: 16 | O23: =M23-ROUNDUP(K23/2,0) -> 37 | P23: =IFS(F23="Yes",3,F23="No",0,F23="Confirmed",3,F23="unk",0) -> 3 | Q23: =IFS(L23="Tied",2,L23="Won",5,L23="Lost",0,L23="n/a",0) -> 5 | R23: 4 | S23: 3 | T23: 3 | U23: =SUM(P23:T23) -> 18
A24: W06 | B24: 46189 | C24: Broken Tee | D24: Front | E24: Zach | F24: Confirmed | G24: - | H24: Bird | I24: Brandt | J24: Joe | K24: 19.4 | L24: Tied | M24: 46 | N24: 15 | O24: =M24-ROUNDUP(K24/2,0) -> 36 | P24: =IFS(F24="Yes",3,F24="No",0,F24="Confirmed",3,F24="unk",0) -> 3 | Q24: =IFS(L24="Tied",2,L24="Won",5,L24="Lost",0,L24="n/a",0) -> 2 | R24: 2 | S24: 4 | T24: 4 | U24: =SUM(P24:T24) -> 15
A25: W05 | B25: 46182 | C25: Fox Hollow | D25: Links | E25: Bird | F25: No | G25: - | H25: - | I25: - | J25: - | K25: - | L25: n/a | M25: - | N25: - | O25: - | P25: =IFS(F25="Yes",3,F25="No",0,F25="Confirmed",3,F25="unk",0) -> 0 | Q25: =IFS(L25="Tied",2,L25="Won",5,L25="Lost",0,L25="n/a",0) -> 0 | R25: 0 | S25: 0 | T25: 0 | U25: =SUM(P25:T25) -> 0
A26: W05 | B26: 46182 | C26: Fox Hollow | D26: Links | E26: Brandt | F26: No | G26: - | H26: - | I26: - | J26: - | K26: - | L26: n/a | M26: - | N26: - | O26: - | P26: =IFS(F26="Yes",3,F26="No",0,F26="Confirmed",3,F26="unk",0) -> 0 | Q26: =IFS(L26="Tied",2,L26="Won",5,L26="Lost",0,L26="n/a",0) -> 0 | R26: 0 | S26: 0 | T26: 0 | U26: =SUM(P26:T26) -> 0
A27: W05 | B27: 46182 | C27: Fox Hollow | D27: Links | E27: Bryan | F27: Confirmed | G27: - | H27: 1v1v1 | I27: Stefan | J27: Jared | K27: 13.1 | L27: Tied | M27: 43 | N27: 19 | O27: =M27-ROUNDUP(K27/2,0) -> 36 | P27: =IFS(F27="Yes",3,F27="No",0,F27="Confirmed",3,F27="unk",0) -> 3 | Q27: =IFS(L27="Tied",2,L27="Won",5,L27="Lost",0,L27="n/a",0) -> 2 | R27: 4 | S27: 4 | T27: 1 | U27: =SUM(P27:T27) -> 14
A28: W05 | B28: 46182 | C28: Fox Hollow | D28: Links | E28: GT | F28: No | G28: - | H28: - | I28: - | J28: - | K28: - | L28: n/a | M28: - | N28: - | O28: - | P28: =IFS(F28="Yes",3,F28="No",0,F28="Confirmed",3,F28="unk",0) -> 0 | Q28: =IFS(L28="Tied",2,L28="Won",5,L28="Lost",0,L28="n/a",0) -> 0 | R28: 0 | S28: 0 | T28: 0 | U28: =SUM(P28:T28) -> 0
A29: W05 | B29: 46182 | C29: Fox Hollow | D29: Links | E29: Hunter | F29: Confirmed | G29: - | H29: Joey | I29: Zach | J29: Joe | K29: 27.4 | L29: Won | M29: 58 | N29: 18 | O29: =M29-ROUNDUP(K29/2,0) -> 44 | P29: =IFS(F29="Yes",3,F29="No",0,F29="Confirmed",3,F29="unk",0) -> 3 | Q29: =IFS(L29="Tied",2,L29="Won",5,L29="Lost",0,L29="n/a",0) -> 5 | R29: 0 | S29: 0 | T29: 2 | U29: =SUM(P29:T29) -> 10
A30: W05 | B30: 46182 | C30: Fox Hollow | D30: Links | E30: Jared | F30: Confirmed | G30: - | H30: 1v1v1 | I30: Stefan | J30: Bryan | K30: 28.9 | L30: Tied | M30: 58 | N30: 20 | O30: =M30-ROUNDUP(K30/2,0) -> 43 | P30: =IFS(F30="Yes",3,F30="No",0,F30="Confirmed",3,F30="unk",0) -> 3 | Q30: =IFS(L30="Tied",2,L30="Won",5,L30="Lost",0,L30="n/a",0) -> 2 | R30: 0 | S30: 0 | T30: 1 | U30: =SUM(P30:T30) -> 6
A31: W05 | B31: 46182 | C31: Fox Hollow | D31: Links | E31: Joe | F31: Confirmed | G31: - | H31: Zach | I31: Hunter | J31: Joey | K31: 18.1 | L31: Lost | M31: 49 | N31: 19 | O31: =M31-ROUNDUP(K31/2,0) -> 39 | P31: =IFS(F31="Yes",3,F31="No",0,F31="Confirmed",3,F31="unk",0) -> 3 | Q31: =IFS(L31="Tied",2,L31="Won",5,L31="Lost",0,L31="n/a",0) -> 0 | R31: 2 | S31: 2 | T31: 1 | U31: =SUM(P31:T31) -> 8
A32: W05 | B32: 46182 | C32: Fox Hollow | D32: Links | E32: Joey | F32: Confirmed | G32: - | H32: Hunter | I32: Zach | J32: Joe | K32: 11.5 | L32: Won | M32: 41 | N32: 17 | O32: =M32-ROUNDUP(K32/2,0) -> 35 | P32: =IFS(F32="Yes",3,F32="No",0,F32="Confirmed",3,F32="unk",0) -> 3 | Q32: =IFS(L32="Tied",2,L32="Won",5,L32="Lost",0,L32="n/a",0) -> 5 | R32: 6 | S32: 5 | T32: 3 | U32: =SUM(P32:T32) -> 22
A33: W05 | B33: 46182 | C33: Fox Hollow | D33: Links | E33: John | F33: No | G33: - | H33: - | I33: - | J33: - | K33: - | L33: n/a | M33: - | N33: - | O33: - | P33: =IFS(F33="Yes",3,F33="No",0,F33="Confirmed",3,F33="unk",0) -> 0 | Q33: =IFS(L33="Tied",2,L33="Won",5,L33="Lost",0,L33="n/a",0) -> 0 | R33: 0 | S33: 0 | T33: 0 | U33: =SUM(P33:T33) -> 0
A34: W05 | B34: 46182 | C34: Fox Hollow | D34: Links | E34: Stefan | F34: Confirmed | G34: - | H34: 1v1v1 | I34: Bryan | J34: Jared | K34: 11.7 | L34: Tied | M34: 44 | N34: 16 | O34: =M34-ROUNDUP(K34/2,0) -> 38 | P34: =IFS(F34="Yes",3,F34="No",0,F34="Confirmed",3,F34="unk",0) -> 3 | Q34: =IFS(L34="Tied",2,L34="Won",5,L34="Lost",0,L34="n/a",0) -> 2 | R34: 3 | S34: 3 | T34: 4 | U34: =SUM(P34:T34) -> 15
A35: W05 | B35: 46182 | C35: Fox Hollow | D35: Links | E35: Zach | F35: Confirmed | G35: - | H35: Joe | I35: Hunter | J35: Joey | K35: 19 | L35: Lost | M35: 51 | N35: 16 | O35: =M35-ROUNDUP(K35/2,0) -> 41 | P35: =IFS(F35="Yes",3,F35="No",0,F35="Confirmed",3,F35="unk",0) -> 3 | Q35: =IFS(L35="Tied",2,L35="Won",5,L35="Lost",0,L35="n/a",0) -> 0 | R35: 1 | S35: 1 | T35: 4 | U35: =SUM(P35:T35) -> 9
A36: W04 | B36: 46175 | C36: Broken Tee | D36: Front | E36: Bird | F36: Confirmed | G36: - | H36: Stefan | I36: Bryan | J36: Zach | K36: 15.3 | L36: Won | M36: 44 | N36: 18 | O36: =M36-ROUNDUP(K36/2,0) -> 36 | P36: =IFS(F36="Yes",3,F36="No",0,F36="Confirmed",3,F36="unk",0) -> 3 | Q36: =IFS(L36="Tied",2,L36="Won",5,L36="Lost",0,L36="n/a",0) -> 5 | R36: 3 | S36: 4 | T36: 0 | U36: =SUM(P36:T36) -> 15
A37: W04 | B37: 46175 | C37: Broken Tee | D37: Front | E37: Brandt | F37: No | G37: - | H37: - | I37: - | J37: - | K37: - | L37: n/a | M37: - | N37: - | O37: - | P37: =IFS(F37="Yes",3,F37="No",0,F37="Confirmed",3,F37="unk",0) -> 0 | Q37: =IFS(L37="Tied",2,L37="Won",5,L37="Lost",0,L37="n/a",0) -> 0 | R37: 0 | S37: 0 | T37: 0 | U37: 0
A38: W04 | B38: 46175 | C38: Broken Tee | D38: Front | E38: Bryan | F38: Confirmed | G38: - | H38: Zach | I38: Stefan | J38: Bird | K38: 12.8 | L38: Lost | M38: 43 | N38: 16 | O38: =M38-ROUNDUP(K38/2,0) -> 36 | P38: =IFS(F38="Yes",3,F38="No",0,F38="Confirmed",3,F38="unk",0) -> 3 | Q38: =IFS(L38="Tied",2,L38="Won",5,L38="Lost",0,L38="n/a",0) -> 0 | R38: 4 | S38: 4 | T38: 2 | U38: =SUM(P38:T38) -> 13
A39: W04 | B39: 46175 | C39: Broken Tee | D39: Front | E39: GT | F39: Confirmed | G39: - | H39: Joe | I39: Hunter | J39: John | K39: 13.3 | L39: Won | M39: 48 | N39: 18 | O39: =M39-ROUNDUP(K39/2,0) -> 41 | P39: =IFS(F39="Yes",3,F39="No",0,F39="Confirmed",3,F39="unk",0) -> 3 | Q39: =IFS(L39="Tied",2,L39="Won",5,L39="Lost",0,L39="n/a",0) -> 5 | R39: 1 | S39: 0 | T39: 0 | U39: =SUM(P39:T39) -> 9
A40: W04 | B40: 46175 | C40: Broken Tee | D40: Front | E40: Hunter | F40: Confirmed | G40: - | H40: John | I40: GT | J40: Joe | K40: 27.4 | L40: Lost | M40: 54 | N40: 14 | O40: =M40-ROUNDUP(K40/2,0) -> 40 | P40: =IFS(F40="Yes",3,F40="No",0,F40="Confirmed",3,F40="unk",0) -> 3 | Q40: =IFS(L40="Tied",2,L40="Won",5,L40="Lost",0,L40="n/a",0) -> 0 | R40: 0 | S40: 1 | T40: 3 | U40: =SUM(P40:T40) -> 7
...

Sheet Match Generator
A1: d
B2: 06/22 Weekly Matches Broken Tee
B5: 0.73611111 | H5: {=INDEX(B6:F6, MATCH(MIN(B7:F7), B7:F7, 0))} -> GT | I5: gives:
B6: Bird | C6: vs. | D6: GT | E6: vs. | F6: Bryan | H6: Bryan | I6: =MEDIAN(B6:F7)-MIN(B6:F7) -> 0 | J6: strokes | L6: Bryan | M6: gives:
B7: {=ROUNDUP(XLOOKUP(B6,'Match Generator'!$B$38:$B$48,'Match Generator'!$C$38:$C$48)/2,0)} -> 8 | D7: {=ROUNDUP(XLOOKUP(D6,'Match Generator'!$B$38:$B$48,'Match Generator'!$C$38:$C$48)/2,0)} -> 7 | F7: {=ROUNDUP(XLOOKUP(F6,'Match Generator'!$B$38:$B$48,'Match Generator'!$C$38:$C$48)/2,0)} -> 7 | H7: {=INDEX(B6:F6, MATCH(MAX(B7:F7), B7:F7, 0))} -> Bird | I7: =MAX(B6:F7)-MIN(B6:F7) -> 1 | J7: strokes | L7: {=INDEX(B6:F6, MATCH(MAX(B7:F7), B7:F7, 0))} -> Bird | M7: =MAX(B6:F7)-MEDIAN(B6:F7) -> 1
B9: 0.74305556
B10: Joe | D10: vs. | E10: Zach
B11: {=ROUNDUP(XLOOKUP(B10,'Match Generator'!$B$38:$B$48,'Match Generator'!$C$38:$C$48)/2,0)} -> 10 | D11: =ABS(B11-E11) -> 0 | E11: {=ROUNDUP(XLOOKUP(B10,'Match Generator'!$B$38:$B$48,'Match Generator'!$C$38:$C$48)/2,0)} -> 10
B23: 2v2
F24: vs.
B25: HCP: | C25: {=ROUNDUP(XLOOKUP(B24,'Match Generator'!$B$38:$B$48,'Match Generator'!$C$38:$C$48)/2,0)} -> #N/A | D25: HCP: | E25: {=ROUNDUP(XLOOKUP(D24,'Match Generator'!$B$38:$B$48,'Match Generator'!$C$38:$C$48)/2,0)} -> #N/A | G25: HCP: | H25: {=ROUNDUP(XLOOKUP(G24,'Match Generator'!$B$38:$B$48,'Match Generator'!$C$38:$C$48)/2,0)} -> #N/A | I25: HCP: | J25: {=ROUNDUP(XLOOKUP(I24,'Match Generator'!$B$38:$B$48,'Match Generator'!$C$38:$C$48)/2,0)} -> #N/A
B26: Strokes: | C26: =C25-MIN($C25,$E25,$H25,$J25) -> #N/A | D26: Strokes: | E26: =E25-MIN($C25,$E25,$H25,$J25) -> #N/A | G26: Strokes: | H26: =H25-MIN($C25,$E25,$H25,$J25) -> #N/A | I26: Strokes: | J26: =J25-MIN($C25,$E25,$H25,$J25) -> #N/A
B28: 1v1
D29: vs.
B30: {=ROUNDUP(XLOOKUP(B29,'Match Generator'!$B$38:$B$48,'Match Generator'!$C$38:$C$48)/2,0)} -> #N/A | D30: =ABS(B30-E30) -> #N/A | E30: {=ROUNDUP(XLOOKUP(E29,'Match Generator'!$B$38:$B$48,'Match Generator'!$C$38:$C$48)/2,0)} -> #N/A
B32: 1v1v1 | H32: {=INDEX(B33:F33, MATCH(MIN(B34:F34), B34:F34, 0))} -> #N/A | I32: gives:
C33: vs. | E33: vs. | H33: {=INDEX(B33:F33, MATCH(MEDIAN(B34:F34), B34:F34, 0))} -> #N/A | I33: =MEDIAN(B33:F34)-MIN(B33:F34) -> #N/A | J33: strokes | L33: {=INDEX(B33:F33, MATCH(MEDIAN(B34:F34), B34:F34, 0))} -> #N/A | M33: gives:
B34: {=ROUNDUP(XLOOKUP(B33,'Match Generator'!$B$38:$B$48,'Match Generator'!$C$38:$C$48)/2,0)} -> #N/A | D34: {=ROUNDUP(XLOOKUP(D33,'Match Generator'!$B$38:$B$48,'Match Generator'!$C$38:$C$48)/2,0)} -> #N/A | F34: {=ROUNDUP(XLOOKUP(F33,'Match Generator'!$B$38:$B$48,'Match Generator'!$C$38:$C$48)/2,0)} -> #N/A | H34: {=INDEX(B33:F33, MATCH(MAX(B34:F34), B34:F34, 0))} -> #N/A | I34: =MAX(B33:F34)-MIN(B33:F34) -> #N/A | J34: strokes | L34: {=INDEX(B33:F33, MATCH(MAX(B34:F34), B34:F34, 0))} -> #N/A | M34: =MAX(B33:F34)-MEDIAN(B33:F34) -> #N/A | N34: strokes
C36: https://wheelofnames.com | E36: Group
B37: Zach | C37: 19 | D37: Confirmed | E37: 3
B38: Joe | C38: 18.3 | D38: Confirmed | E38: 4
B39: Bird | C39: 15.8 | D39: Confirmed | E39: 9
B40: GT | C40: 13.2 | D40: Confirmed | E40: 2
B41: Hunter | C41: 27.4 | D41: No | E41: 5
B42: Brandt | C42: 10.5 | D42: No | E42: 6
B43: John | C43: 33.1 | D43: No | E43: 7
B44: Joey | C44: 11.1 | D44: No | E44: 8
B45: Bryan | C45: 13.1 | D45: Confirmed | E45: 1
B46: Jared | C46: 24.9 | D46: No | E46: 10
B47: Stefan | C47: 11.5 | D47: No | E47: 11

Sheet Copy of Match Generator
A1: d
B2: 06/09(ha nice) Weekly Matches Fox Hollow
B5: 0.73541667
B6: Joe | D6: Zach | F6: vs. | G6: Hunter | I6: Joey
B7: HCP: | C7: {=ROUNDUP(XLOOKUP(B6,'Copy of Match Generator'!$B$37:$B$47,'Copy of Match Generator'!$C$37:$C$47)/2,0)} -> 10 | D7: HCP: | E7: {=ROUNDUP(XLOOKUP(D6,'Copy of Match Generator'!$B$37:$B$47,'Copy of Match Generator'!$C$37:$C$47)/2,0)} -> 10 | G7: HCP: | H7: {=ROUNDUP(XLOOKUP(G6,'Copy of Match Generator'!$B$37:$B$47,'Copy of Match Generator'!$C$37:$C$47)/2,0)} -> 14 | I7: HCP: | J7: {=ROUNDUP(XLOOKUP(I6,'Copy of Match Generator'!$B$37:$B$47,'Copy of Match Generator'!$C$37:$C$47)/2,0)} -> 6
B8: Strokes: | C8: =C7-MIN($C7,$E7,$H7,$J7) -> 4 | D8: Strokes: | E8: =E7-MIN($C7,$E7,$H7,$J7) -> 4 | G8: Strokes: | H8: =H7-MIN($C7,$E7,$H7,$J7) -> 8 | I8: Strokes: | J8: =J7-MIN($C7,$E7,$H7,$J7) -> 0
B10: 0.74166667
B11: GT | D11: Bryan | F11: vs. | G11: Stefan | I11: Jared
B12: HCP: | C12: {=ROUNDUP(XLOOKUP(B11,'Copy of Match Generator'!$B$37:$B$47,'Copy of Match Generator'!$C$37:$C$47)/2,0)} -> 7 | D12: HCP: | E12: {=ROUNDUP(XLOOKUP(D11,'Copy of Match Generator'!$B$37:$B$47,'Copy of Match Generator'!$C$37:$C$47)/2,0)} -> 7 | G12: HCP: | H12: {=ROUNDUP(XLOOKUP(G11,'Copy of Match Generator'!$B$37:$B$47,'Copy of Match Generator'!$C$37:$C$47)/2,0)} -> 6 | I12: HCP: | J12: {=ROUNDUP(XLOOKUP(I11,'Copy of Match Generator'!$B$37:$B$47,'Copy of Match Generator'!$C$37:$C$47)/2,0)} -> 15
B13: Strokes: | C13: =C12-MIN($C12,$E12,$H12,$J12) -> 1 | D13: Strokes: | E13: =E12-MIN($C12,$E12,$H12,$J12) -> 1 | G13: Strokes: | H13: =H12-MIN($C12,$E12,$H12,$J12) -> 0 | I13: Strokes: | J13: =J12-MIN($C12,$E12,$H12,$J12) -> 9
B23: 2v2
F24: vs.
B25: HCP: | C25: {=ROUNDUP(XLOOKUP(B24,'Copy of Match Generator'!$B$37:$B$47,'Copy of Match Generator'!$C$37:$C$47)/2,0)} -> #N/A | D25: HCP: | E25: {=ROUNDUP(XLOOKUP(D24,'Copy of Match Generator'!$B$37:$B$47,'Copy of Match Generator'!$C$37:$C$47)/2,0)} -> #N/A | G25: HCP: | H25: {=ROUNDUP(XLOOKUP(G24,'Copy of Match Generator'!$B$37:$B$47,'Copy of Match Generator'!$C$37:$C$47)/2,0)} -> #N/A | I25: HCP: | J25: {=ROUNDUP(XLOOKUP(I24,'Copy of Match Generator'!$B$37:$B$47,'Copy of Match Generator'!$C$37:$C$47)/2,0)} -> #N/A
B26: Strokes: | C26: =C25-MIN($C25,$E25,$H25,$J25) -> #N/A | D26: Strokes: | E26: =E25-MIN($C25,$E25,$H25,$J25) -> #N/A | G26: Strokes: | H26: =H25-MIN($C25,$E25,$H25,$J25) -> #N/A | I26: Strokes: | J26: =J25-MIN($C25,$E25,$H25,$J25) -> #N/A
B28: 1v1
D29: vs.
B30: {=ROUNDUP(XLOOKUP(B29,'Copy of Match Generator'!$B$37:$B$47,'Copy of Match Generator'!$C$37:$C$47)/2,0)} -> #N/A | D30: =ABS(B30-E30) -> #N/A | E30: {=ROUNDUP(XLOOKUP(E29,'Copy of Match Generator'!$B$37:$B$47,'Copy of Match Generator'!$C$37:$C$47)/2,0)} -> #N/A
B32: 1v1v1 | H32: {=INDEX(B33:F33, MATCH(MIN(B34:F34), B34:F34, 0))} -> Stefan | I32: gives:
B33: Stefan | C33: vs. | D33: Bryan | E33: vs. | F33: Jared | H33: {=INDEX(B33:F33, MATCH(MEDIAN(B34:F34), B34:F34, 0))} -> Bryan | I33: =MEDIAN(B33:F34)-MIN(B33:F34) -> 1 | J33: strokes | L33: {=INDEX(B33:F33, MATCH(MEDIAN(B34:F34), B34:F34, 0))} -> Bryan | M33: gives:
B34: {=ROUNDUP(XLOOKUP(B33,'Copy of Match Generator'!$B$37:$B$47,'Copy of Match Generator'!$C$37:$C$47)/2,0)} -> 6 | D34: {=ROUNDUP(XLOOKUP(D33,'Copy of Match Generator'!$B$37:$B$47,'Copy of Match Generator'!$C$37:$C$47)/2,0)} -> 7 | F34: {=ROUNDUP(XLOOKUP(F33,'Copy of Match Generator'!$B$37:$B$47,'Copy of Match Generator'!$C$37:$C$47)/2,0)} -> 15 | H34: {=INDEX(B33:F33, MATCH(MAX(B34:F34), B34:F34, 0))} -> Jared | I34: =MAX(B33:F34)-MIN(B33:F34) -> 9 | J34: strokes | L34: {=INDEX(B33:F33, MATCH(MAX(B34:F34), B34:F34, 0))} -> Jared | M34: =MAX(B33:F34)-MEDIAN(B33:F34) -> 8 | N34: strokes
C36: https://wheelofnames.com | E36: Group
B37: Bryan | C37: 13.1 | D37: Confirmed | E37: 1
B38: GT | C38: 13.3 | D38: No | E38: 2
B39: Hunter | C39: 27.4 | D39: Confirmed | E39: 5
B40: Jared | C40: 28.9 | D40: Confirmed | E40: 10
B41: Joe | C41: 18.1 | D41: Confirmed | E41: 4
B42: Brandt | C42: 10 | D42: No | E42: 6
B43: John | C43: 34.5 | D43: No | E43: 7
B44: Joey | C44: 11.5 | D44: Confirmed | E44: 8
B45: Bird | C45: 15.8 | D45: No | E45: 9
B46: Stefan | C46: 11.7 | D46: Confirmed | E46: 11
B47: Zach | C47: 19 | D47: Confirmed | E47: 3

Sheet Scoring Rules
B2: Showing Up | E2: Rank | F2: Gross Strokes | G2: Net Strokes | H2: Putts
B3: Showed | C3: 3 | E3: 1 | F3: 6 | G3: 5 | H3: 4
B4: No Show | C4: 0 | E4: 2 | F4: 4 | G4: 4 | H4: 3
E5: 3 | F5: 3 | G5: 3 | H5: 2
B6: Match Play | E6: 4 | F6: 2 | G6: 2 | H6: 1
B7: Win | C7: 5 | E7: 5 | F7: 1 | G7: 1 | H7: 0
B8: Tie | C8: 2 | E8: 6+ | F8: 0 | G8: 0 | H8: 0
B9: Loss | C9: 0

Sheet Schedule
A1: Date | B1: Course | C1: Time 1 | D1: Time 2 | E1: Time 3
A2: 46147 | B2: Fossil Trace | C2: n/a | D2: n/a | E2: n/a
A3: 46154 | B3: Overland | C3: 0.73611111 | D3: 0.74305556 | E3: 0.75
A4: 46161 | B4: Indian Tree | C4: 0.72222222 | D4: 0.72916667 | E4: n/a
A5: 46168 | B5: Overland | C5: 0.73611111 | D5: 0.74305556 | E5: 0.75
A6: 46175 | B6: Broken Tee | C6: 0.72916667 | D6: 0.73611111 | E6: n/a
A7: 46182 | B7: Fox Hollow | C7: 0.73541667 | D7: 0.74166667 | E7: n/a
A8: 46189 | B8: Broken Tee | C8: 0.73611111 | D8: 0.74305556 | E8: n/a
A9: 46196 | B9: Broken Tee | C9: 0.23611111 | D9: 0.74305556 | E9: 0.75
A10: 46203
A11: 46210
A12: 46217
A13: 46224
A14: 46231
A15: 46238
A16: 46245
A17: 46252
A18: 46259
A19: 46266
A20: 46273
A21: 46280
... A23: 46294

Sheet Courses
B2: Course | C2: Link | D2: Rank
B3: DCG - Willis Case | C3: https://app.membersports.com/tee-times/3629/20573/1 | D3: 25.5
B4: Fox Hollow | C4: https://app.membersports.com/tee-times/3703/20589/0 | D4: 24.75
B5: Homestead | C5: https://app.membersports.com/tee-times/3807/4902/0 | D5: 24.75
B6: Fossil Trace | C6: https://fossiltrace.cps.golf/onlineresweb/search-teetime?TeeOffTimeMin=0&TeeOffTimeMax=23.999722222222225 | D6: 23.25
B7: DCG - Overland | C7: https://app.membersports.com/tee-times/3629/20573/1 | D7: 22.25
B8: Indian Tree | C8: https://indiantree.cps.golf/onlineresweb/search-teetime?TeeOffTimeMin=0&TeeOffTimeMax=23 | D8: 20.25
B9: West Woods | C9: https://www.westwoodsgolf.com/teetimes | D9: 18.75
B10: DCG - City Park | C10: https://app.membersports.com/tee-times/3629/20573/1 | D10: 18.5
B11: Broken Tee | C11: https://app.membersports.com/tee-times/3689/4748/0 | D11: 17
B12: Legacy Ridge | C12: https://cityofwestminster.cps.golf/onlineresweb/search-teetime?TeeOffTimeMin=0&TeeOffTimeMax=23 | D12: 15
B13: Applewood | C13: https://apimanager-cc11.clubcaddie.com/webapi/view/hbfdabab/slots?date=05%2F26%2F2026&player=1&ratetype=any&Interaction=aag6k8m9kpkgean2bg6ct6g8vb | D13: 13.25
B14: Hyland Hills | C14: https://www.golfhylandhills.com/teetimes/ | D14: 11

Sheet 18
B1: Friends | C1: Group
A2: Bird | B2: Yes
A3: Joey | B3: Yes
A4: Zach | B4: Yes | C4: Yes
A5: Joe | B5: Yes | C5: Yes
A6: GT | B6: Yes | C6: Yes
A7: Hunter | B7: Yes | C7: Yes
A8: Brandt | B8: Yes | C8: Yes
A9: Jared | B9: Yes
A10: John | B10: Yes
A11: Stefan | B11: No

Sheet 519 Copy of Match Generator
B2: 5/19 Weekly Matches Indian Tree | H2: 1v1v1 strokes given for match play
B4: 0.72222222 | H4: {=INDEX(B5:F5, MATCH(MIN(B6:F6), B6:F6, 0))} -> Bryan | I4: gives:
B5: Bryan | C5: vs. | D5: Zach | E5: vs. | F5: Bird | H5: {=INDEX(B5:F5, MATCH(MEDIAN(B6:F6), B6:F6, 0))} -> Bird | I5: =MEDIAN(B5:F6)-MIN(B5:F6) -> 1 | J5: strokes | L5: {=INDEX(B5:F5, MATCH(MEDIAN(B6:F6), B6:F6, 0))} -> Bird | M5: gives:
B6: {=ROUNDUP(XLOOKUP(B5,'519 Copy of Match Generator'!$B$36:$B$46,'519 Copy of Match Generator'!$C$36:$C$46)/2,0)} -> 7 | D6: {=ROUNDUP(XLOOKUP(D5,'519 Copy of Match Generator'!$B$36:$B$46,'519 Copy of Match Generator'!$C$36:$C$46)/2,0)} -> 9 | F6: {=ROUNDUP(XLOOKUP(F5,'519 Copy of Match Generator'!$B$36:$B$46,'519 Copy of Match Generator'!$C$36:$C$46)/2,0)} -> 8 | H6: {=INDEX(B5:F5, MATCH(MAX(B6:F6), B6:F6, 0))} -> Zach | I6: =MAX(B5:F6)-MIN(B5:F6) -> 2 | J6: strokes | L6: {=INDEX(B5:F5, MATCH(MAX(B6:F6), B6:F6, 0))} -> Zach | M6: =MAX(B5:F6)-MEDIAN(B5:F6) -> 1 | N6: strokes
B8: 0.72916667 | H8: {=INDEX(B9:F9, MATCH(MIN(B10:F10), B10:F10, 0))} -> Joey | I8: gives:
B9: Joey | C9: vs. | D9: GT | E9: vs. | F9: Joe | H9: {=INDEX(B9:F9, MATCH(MEDIAN(B10:F10), B10:F10, 0))} -> GT | I9: =MEDIAN(B9:F10)-MIN(B9:F10) -> 1 | J9: strokes | L9: {=INDEX(B9:F9, MATCH(MEDIAN(B10:F10), B10:F10, 0))} -> GT | M9: gives:
B10: {=ROUNDUP(XLOOKUP(B9,'519 Copy of Match Generator'!$B$36:$B$46,'519 Copy of Match Generator'!$C$36:$C$46)/2,0)} -> 6 | D10: {=ROUNDUP(XLOOKUP(D9,'519 Copy of Match Generator'!$B$36:$B$46,'519 Copy of Match Generator'!$C$36:$C$46)/2,0)} -> 7 | F10: {=ROUNDUP(XLOOKUP(F9,'519 Copy of Match Generator'!$B$36:$B$46,'519 Copy of Match Generator'!$C$36:$C$46)/2,0)} -> 10 | H10: {=INDEX(B9:F9, MATCH(MAX(B10:F10), B10:F10, 0))} -> Joe | I10: =MAX(B9:F10)-MIN(B9:F10) -> 4 | J10: strokes | L10: {=INDEX(B9:F9, MATCH(MAX(B10:F10), B10:F10, 0))} -> Joe | M10: =MAX(B9:F10)-MEDIAN(B9:F10) -> 3 | N10: strokes
B22: 2v2
D23: vs.
B24: {=ROUNDUP(XLOOKUP(B23,'519 Copy of Match Generator'!$B$36:$B$46,'519 Copy of Match Generator'!$C$36:$C$46)/2,0)} -> #N/A | C24: {=ROUNDUP(XLOOKUP(C23,'519 Copy of Match Generator'!$B$36:$B$46,'519 Copy of Match Generator'!$C$36:$C$46)/2,0)} -> #N/A | D24: Strokes | E24: {=ROUNDUP(XLOOKUP(E23,'519 Copy of Match Generator'!$B$36:$B$46,'519 Copy of Match Generator'!$C$36:$C$46)/2,0)} -> #N/A | F24: {=ROUNDUP(XLOOKUP(F23,'519 Copy of Match Generator'!$B$36:$B$46,'519 Copy of Match Generator'!$C$36:$C$46)/2,0)} -> #N/A
B25: Team Handicap: | C25: =B24+C24 -> #N/A | D25: =ABS(C25-F25) -> #N/A | E25: Team Handicap: | F25: =E24+F24 -> #N/A
B27: 1v1
D28: vs.
B29: {=ROUNDUP(XLOOKUP(B28,'519 Copy of Match Generator'!$B$36:$B$46,'519 Copy of Match Generator'!$C$36:$C$46)/2,0)} -> #N/A | D29: =ABS(B29-E29) -> #N/A | E29: {=ROUNDUP(XLOOKUP(E28,'519 Copy of Match Generator'!$B$36:$B$46,'519 Copy of Match Generator'!$C$36:$C$46)/2,0)} -> #N/A
B31: 1v1v1 | H31: {=INDEX(B32:F32, MATCH(MIN(B33:F33), B33:F33, 0))} -> #N/A | I31: gives:
C32: vs. | E32: vs. | H32: {=INDEX(B32:F32, MATCH(MEDIAN(B33:F33), B33:F33, 0))} -> #N/A | I32: =MEDIAN(B32:F33)-MIN(B32:F33) -> #N/A | J32: strokes | L32: {=INDEX(B32:F32, MATCH(MEDIAN(B33:F33), B33:F33, 0))} -> #N/A | M32: gives:
B33: {=ROUNDUP(XLOOKUP(B32,'519 Copy of Match Generator'!$B$36:$B$46,'519 Copy of Match Generator'!$C$36:$C$46)/2,0)} -> #N/A | D33: {=ROUNDUP(XLOOKUP(D32,'519 Copy of Match Generator'!$B$36:$B$46,'519 Copy of Match Generator'!$C$36:$C$46)/2,0)} -> #N/A | F33: {=ROUNDUP(XLOOKUP(F32,'519 Copy of Match Generator'!$B$36:$B$46,'519 Copy of Match Generator'!$C$36:$C$46)/2,0)} -> #N/A | H33: {=INDEX(B32:F32, MATCH(MAX(B33:F33), B33:F33, 0))} -> #N/A | I33: =MAX(B32:F33)-MIN(B32:F33) -> #N/A | J33: strokes | L33: {=INDEX(B32:F32, MATCH(MAX(B33:F33), B33:F33, 0))} -> #N/A | M33: =MAX(B32:F33)-MEDIAN(B32:F33) -> #N/A | N33: strokes
C35: https://wheelofnames.com | E35: Group
B36: Bird | C36: 15.3 | D36: Confirmed | E36: 9
B37: Bryan | C37: 13.1 | D37: Confirmed | E37: 1
B38: GT | C38: 13.6 | D38: Confirmed | E38: 2
B39: Joe | C39: 18.2 | D39: Confirmed | E39: 4
B40: Joey | C40: 11.6 | D40: Confirmed | E40: 8
B41: Zach | C41: 17.8 | D41: Confirmed | E41: 3
B42: Brandt | C42: 10 | D42: No | E42: 6
B43: Hunter | C43: 27.4 | D43: No | E43: 5
B44: Jared | C44: 28 | D44: No | E44: no
B45: John | C45: 28.8 | D45: No | E45: 7
B46: Stefan | C46: - | D46: No | E46: no

Sheet 0512 Match Generator
B2: 5/12 Weekly Matches | H2: 1v1v1 strokes given for match play
B5: 0.73611111 | H5: {=INDEX(B6:F6, MATCH(MIN(B7:F7), B7:F7, 0))} -> Bryan | I5: gives:
B6: Bryan | C6: vs. | D6: Joe | E6: vs. | F6: John | H6: {=INDEX(B6:F6, MATCH(MEDIAN(B7:F7), B7:F7, 0))} -> Joe | I6: =MEDIAN(B6:F7)-MIN(B6:F7) -> 2 | J6: strokes | L6: {=INDEX(B6:F6, MATCH(MEDIAN(B7:F7), B7:F7, 0))} -> Joe | M6: gives:
B7: {=ROUNDUP(XLOOKUP(B6,'0512 Match Generator'!$B$47:$B$57,'0512 Match Generator'!$C$47:$C$57)/2,0)} -> 7 | D7: {=ROUNDUP(XLOOKUP(D6,'0512 Match Generator'!$B$47:$B$57,'0512 Match Generator'!$C$47:$C$57)/2,0)} -> 9 | F7: {=ROUNDUP(XLOOKUP(F6,'0512 Match Generator'!$B$47:$B$57,'0512 Match Generator'!$C$47:$C$57)/2,0)} -> 14 | H7: {=INDEX(B6:F6, MATCH(MAX(B7:F7), B7:F7, 0))} -> John | I7: =MAX(B6:F7)-MIN(B6:F7) -> 7 | J7: strokes | L7: {=INDEX(B6:F6, MATCH(MAX(B7:F7), B7:F7, 0))} -> John | M7: =MAX(B6:F7)-MEDIAN(B6:F7) -> 5 | N7: strokes
B9: 0.74305556 | H9: {=INDEX(B10:F10, MATCH(MIN(B11:F11), B11:F11, 0))} -> Brandt | I9: gives:
B10: Brandt | C10: vs. | D10: Bird | E10: vs. | F10: Hunter | H10: {=INDEX(B10:F10, MATCH(MEDIAN(B11:F11), B11:F11, 0))} -> Bird | I10: =MEDIAN(B10:F11)-MIN(B10:F11) -> 4 | J10: strokes | L10: {=INDEX(B10:F10, MATCH(MEDIAN(B11:F11), B11:F11, 0))} -> Bird | M10: gives:
B11: {=ROUNDUP(XLOOKUP(B10,'0512 Match Generator'!$B$47:$B$57,'0512 Match Generator'!$C$47:$C$57)/2,0)} -> 5 | D11: {=ROUNDUP(XLOOKUP(D10,'0512 Match Generator'!$B$47:$B$57,'0512 Match Generator'!$C$47:$C$57)/2,0)} -> 9 | F11: {=ROUNDUP(XLOOKUP(F10,'0512 Match Generator'!$B$47:$B$57,'0512 Match Generator'!$C$47:$C$57)/2,0)} -> 14 | H11: {=INDEX(B10:F10, MATCH(MAX(B11:F11), B11:F11, 0))} -> Hunter | I11: =MAX(B10:F11)-MIN(B10:F11) -> 9 | J11: strokes | L11: {=INDEX(B10:F10, MATCH(MAX(B11:F11), B11:F11, 0))} -> Hunter | M11: =MAX(B10:F11)-MEDIAN(B10:F11) -> 5 | N11: strokes
B13: 0.75 | H13: {=INDEX(B14:F14, MATCH(MIN(B15:F15), B15:F15, 0))} -> Joey | I13: gives:
B14: GT | C14: vs. | D14: Zach | E14: vs. | F14: Joey | H14: {=INDEX(B14:F14, MATCH(MEDIAN(B15:F15), B15:F15, 0))} -> GT | I14: =MEDIAN(B14:F15)-MIN(B14:F15) -> 1 | J14: strokes | L14: {=INDEX(B14:F14, MATCH(MEDIAN(B15:F15), B15:F15, 0))} -> GT | M14: gives:
B15: {=ROUNDUP(XLOOKUP(B14,'0512 Match Generator'!$B$47:$B$57,'0512 Match Generator'!$C$47:$C$57)/2,0)} -> 7 | D15: {=ROUNDUP(XLOOKUP(D14,'0512 Match Generator'!$B$47:$B$57,'0512 Match Generator'!$C$47:$C$57)/2,0)} -> 11 | F15: {=ROUNDUP(XLOOKUP(F14,'0512 Match Generator'!$B$47:$B$57,'0512 Match Generator'!$C$47:$C$57)/2,0)} -> 6 | H15: {=INDEX(B14:F14, MATCH(MAX(B15:F15), B15:F15, 0))} -> Zach | I15: =MAX(B14:F15)-MIN(B14:F15) -> 5 | J15: strokes | L15: {=INDEX(B14:F14, MATCH(MAX(B15:F15), B15:F15, 0))} -> Zach | M15: =MAX(B14:F15)-MEDIAN(B14:F15) -> 4 | N15: strokes
B33: 2v2
D34: vs.
B35: {=ROUNDUP(XLOOKUP(B34,'0512 Match Generator'!$B$47:$B$57,'0512 Match Generator'!$C$47:$C$57)/2,0)} -> #N/A | C35: {=ROUNDUP(XLOOKUP(C34,'0512 Match Generator'!$B$47:$B$57,'0512 Match Generator'!$C$47:$C$57)/2,0)} -> #N/A | D35: Strokes | E35: {=ROUNDUP(XLOOKUP(E34,'0512 Match Generator'!$B$47:$B$57,'0512 Match Generator'!$C$47:$C$57)/2,0)} -> #N/A | F35: {=ROUNDUP(XLOOKUP(F34,'0512 Match Generator'!$B$47:$B$57,'0512 Match Generator'!$C$47:$C$57)/2,0)} -> #N/A
B36: Team Handicap: | C36: =B35+C35 -> #N/A | D36: =ABS(C36-F36) -> #N/A | E36: Team Handicap: | F36: =E35+F35 -> #N/A
B38: 1v1
D39: vs.
B40: {=ROUNDUP(XLOOKUP(B39,'0512 Match Generator'!$B$47:$B$57,'0512 Match Generator'!$C$47:$C$57)/2,0)} -> #N/A | D40: =ABS(B40-E40) -> #N/A | E40: {=ROUNDUP(XLOOKUP(E39,'0512 Match Generator'!$B$47:$B$57,'0512 Match Generator'!$C$47:$C$57)/2,0)} -> #N/A
B42: 1v1v1 | H42: {=INDEX(B43:F43, MATCH(MIN(B44:F44), B44:F44, 0))} -> #N/A | I42: gives:
C43: vs. | E43: vs. | H43: {=INDEX(B43:F43, MATCH(MEDIAN(B44:F44), B44:F44, 0))} -> #N/A | I43: =MEDIAN(B43:F44)-MIN(B43:F44) -> #N/A | J43: strokes | L43: {=INDEX(B43:F43, MATCH(MEDIAN(B44:F44), B44:F44, 0))} -> #N/A | M43: gives:
B44: {=ROUNDUP(XLOOKUP(B43,'0512 Match Generator'!$B$47:$B$57,'0512 Match Generator'!$C$47:$C$57)/2,0)} -> #N/A | D44: {=ROUNDUP(XLOOKUP(D43,'0512 Match Generator'!$B$47:$B$57,'0512 Match Generator'!$C$47:$C$57)/2,0)} -> #N/A | F44: {=ROUNDUP(XLOOKUP(F43,'0512 Match Generator'!$B$47:$B$57,'0512 Match Generator'!$C$47:$C$57)/2,0)} -> #N/A | H44: {=INDEX(B43:F43, MATCH(MAX(B44:F44), B44:F44, 0))} -> #N/A | I44: =MAX(B43:F44)-MIN(B43:F44) -> #N/A | J44: strokes | L44: {=INDEX(B43:F43, MATCH(MAX(B44:F44), B44:F44, 0))} -> #N/A | M44: =MAX(B43:F44)-MEDIAN(B43:F44) -> #N/A | N44: strokes
C46: https://wheelofnames.com
B47: Bird | C47: 16.8 | D47: Confirmed
B48: Brandt | C48: 9.1 | D48: Confirmed
B49: Bryan | C49: 13.9 | D49: Confirmed
B50: GT | C50: 12.7 | D50: Confirmed
B51: Hunter | C51: 28 | D51: Confirmed
B52: Joe | C52: 17.9 | D52: Confirmed
B53: Joey | C53: 10.9 | D53: Confirmed
B54: John | C54: 28 | D54: Confirmed
B55: Zach | C55: 21 | D55: Confirmed
B56: Jared | C56: 28 | D56: No
B57: Stefan | C57: - | D57: No
B60: Course | C60: Link | D60: Rank
B61: Indian Tree | C61: https://indiantree.cps.golf/onlineresweb/search-teetime?TeeOffTimeMin=0&TeeOffTimeMax=23 | D61: A
B62: Fox Hollow | C62: https://app.membersports.com/tee-times/3703/20589/0 | D62: A
B63: West Woods | D63: A
B64: Broken Tee | D64: A
B65: Overland | D65: A
B66: Willis Case | C66: https://app.membersports.com/tee-times/3629/20573/1
B67: Fossil Trace | C67: https://fossiltrace.cps.golf/onlineresweb/search-teetime?TeeOffTimeMin=0&TeeOffTimeMax=23.999722222222225 | D67: A
...

Sheet Course Preferences
A1: Course | B1: Points | D1: Course | E1: Points
A2: Willis Case | B2: 25.5 | D2: Keystone | E2: 21
A3: Fox Hollow | B3: 24.75 | D3: TPC CO | E3: 19.5
A4: Fossil Trace | B4: 23.25 | D4: The RIdge | E4: 19.5
A5: Overland | B5: 22.25 | D5: Bear Dance | E5: 19.5
A6: Indian Tree | B6: 20.25 | D6: Breck | E6: 18
A7: West Woods | B7: 18.75 | D7: Red Hawk Ridge | E7: 18
A8: City Park | B8: 18.5 | D8: Plum Creek | E8: 15.5
A9: Broken Tee | B9: 17 | D9: Eagle Vail | E9: 14
A10: Legacy Ridge | B10: 15 | D10: CO National | E10: 14
A11: Applewood | B11: 13.25 | D11: Vail | E11: 12.5
A12: Hyland Hills | B12: 11 | D12: Beaver Creek | E12: 11.5
A13: GVR | B13: 9.25 | D13: Haymaker | E13: 9
A14: Walnut Creek | B14: 8.75
A15: Kennedy | B15: 0
B18: Course | C18: Link | D18: Rank | E18: Open?
B19: DCG - Willis Case | C19: https://app.membersports.com/tee-times/3629/20573/1 | D19: 25.5
B20: Fox Hollow | C20: https://app.membersports.com/tee-times/3703/20589/0 | D20: 24.75
B21: Homestead | C21: https://app.membersports.com/tee-times/3807/4902/0 | D21: 24.75
B22: Fossil Trace | C22: https://fossiltrace.cps.golf/onlineresweb/search-teetime?TeeOffTimeMin=0&TeeOffTimeMax=23.999722222222225 | D22: 23.25
B23: DCG - Overland | C23: https://app.membersports.com/tee-times/3629/20573/1 | D23: 22.25
B24: Indian Tree | C24: https://indiantree.cps.golf/onlineresweb/search-teetime?TeeOffTimeMin=0&TeeOffTimeMax=23 | D24: 20.25 | E24: no
B25: West Woods | C25: https://www.westwoodsgolf.com/teetimes | D25: 18.75
B26: DCG - City Park | C26: https://app.membersports.com/tee-times/3629/20573/1 | D26: 18.5
B27: Broken Tee | C27: https://app.membersports.com/tee-times/3689/4748/0 | D27: 17
B28: Legacy Ridge | C28: https://cityofwestminster.cps.golf/onlineresweb/search-teetime?TeeOffTimeMin=0&TeeOffTimeMax=23 | D28: 15
B29: Applewood | C29: https://apimanager-cc11.clubcaddie.com/webapi/view/hbfdabab/slots?date=05%2F26%2F2026&player=1&ratetype=any&Interaction=aag6k8m9kpkgean2bg6ct6g8vb | D29: 13.25 | E29: Open
B30: Hyland Hills | C30: https://www.golfhylandhills.com/teetimes/ | D30: 11 | E30: Yes

Sheet Example Leaderboard
B2: Example Leaderboard | G2: Bragging Rights
B3: Pos. | C3: Golfer | D3: Points | E3: Behind | G3: Golfer | H3: Match Wins | I3: No Shows | J3: Lowest Score
B4: 1 | C4: Joey | D4: =SUMIF('Example Weekly Point Data'!$D:$D, C4, 'Example Weekly Point Data'!$Q:$Q) -> 39 | E4: 0 | G4: =C4 -> Joey | H4: =COUNTIFS('Example Weekly Point Data'!G:G,"Won",'Example Weekly Point Data'!D:D,G4) -> 1 | I4: =COUNTIFS('Example Weekly Point Data'!F:F,"No",'Example Weekly Point Data'!D:D,G4) -> 0 | J4: =MINIFS('Example Weekly Point Data'!I:I,'Example Weekly Point Data'!D:D,G4) -> 43
B5: 2 | C5: Cal | D5: =SUMIF('Example Weekly Point Data'!$D:$D, C5, 'Example Weekly Point Data'!$Q:$Q) -> 37 | E5: =D5-$D$4 -> -2 | G5: =C5 -> Cal | H5: =COUNTIFS('Example Weekly Point Data'!G:G,"Won",'Example Weekly Point Data'!D:D,G5) -> 1 | I5: =COUNTIFS('Example Weekly Point Data'!F:F,"No",'Example Weekly Point Data'!D:D,G5) -> 0 | J5: =MINIFS('Example Weekly Point Data'!I:I,'Example Weekly Point Data'!D:D,G5) -> 47
B6: 3 | C6: Brandt | D6: =SUMIF('Example Weekly Point Data'!$D:$D, C6, 'Example Weekly Point Data'!$Q:$Q) -> 34 | E6: =D6-$D$4 -> -5 | G6: =C6 -> Brandt | H6: =COUNTIFS('Example Weekly Point Data'!G:G,"Won",'Example Weekly Point Data'!D:D,G6) -> 0 | I6: =COUNTIFS('Example Weekly Point Data'!F:F,"No",'Example Weekly Point Data'!D:D,G6) -> 0 | J6: =MINIFS('Example Weekly Point Data'!I:I,'Example Weekly Point Data'!D:D,G6) -> 43
B7: 4 | C7: GT | D7: =SUMIF('Example Weekly Point Data'!$D:$D, C7, 'Example Weekly Point Data'!$Q:$Q) -> 28 | E7: =D7-$D$4 -> -11 | G7: =C7 -> GT | H7: =COUNTIFS('Example Weekly Point Data'!G:G,"Won",'Example Weekly Point Data'!D:D,G7) -> 0 | I7: =COUNTIFS('Example Weekly Point Data'!F:F,"No",'Example Weekly Point Data'!D:D,G7) -> 0 | J7: =MINIFS('Example Weekly Point Data'!I:I,'Example Weekly Point Data'!D:D,G7) -> 46
B8: 5 | C8: Bryan | D8: =SUMIF('Example Weekly Point Data'!$D:$D, C8, 'Example Weekly Point Data'!$Q:$Q) -> 23 | E8: =D8-$D$4 -> -16 | G8: =C8 -> Bryan | H8: =COUNTIFS('Example Weekly Point Data'!G:G,"Won",'Example Weekly Point Data'!D:D,G8) -> 1 | I8: =COUNTIFS('Example Weekly Point Data'!F:F,"No",'Example Weekly Point Data'!D:D,G8) -> 0 | J8: =MINIFS('Example Weekly Point Data'!I:I,'Example Weekly Point Data'!D:D,G8) -> 49
B9: 6 | C9: Zach | D9: =SUMIF('Example Weekly Point Data'!$D:$D, C9, 'Example Weekly Point Data'!$Q:$Q) -> 22 | E9: =D9-$D$4 -> -17 | G9: =C9 -> Zach | H9: =COUNTIFS('Example Weekly Point Data'!G:G,"Won",'Example Weekly Point Data'!D:D,G9) -> 0 | I9: =COUNTIFS('Example Weekly Point Data'!F:F,"No",'Example Weekly Point Data'!D:D,G9) -> 0 | J9: =MINIFS('Example Weekly Point Data'!I:I,'Example Weekly Point Data'!D:D,G9) -> 48
B10: 7 | C10: Joe | D10: =SUMIF('Example Weekly Point Data'!$D:$D, C10, 'Example Weekly Point Data'!$Q:$Q) -> 21 | E10: =D10-$D$4 -> -18 | G10: =C10 -> Joe | H10: =COUNTIFS('Example Weekly Point Data'!G:G,"Won",'Example Weekly Point Data'!D:D,G10) -> 1 | I10: =COUNTIFS('Example Weekly Point Data'!F:F,"No",'Example Weekly Point Data'!D:D,G10) -> 0 | J10: =MINIFS('Example Weekly Point Data'!I:I,'Example Weekly Point Data'!D:D,G10) -> 48
B11: 9 | C11: Jared | D11: =SUMIF('Example Weekly Point Data'!$D:$D, C11, 'Example Weekly Point Data'!$Q:$Q) -> 15 | E11: =D11-$D$4 -> -24 | G11: =C11 -> Jared | H11: =COUNTIFS('Example Weekly Point Data'!G:G,"Won",'Example Weekly Point Data'!D:D,G11) -> 1 | I11: =COUNTIFS('Example Weekly Point Data'!F:F,"No",'Example Weekly Point Data'!D:D,G11) -> 1 | J11: =MINIFS('Example Weekly Point Data'!I:I,'Example Weekly Point Data'!D:D,G11) -> 52
B12: 9 | C12: Bird | D12: =SUMIF('Example Weekly Point Data'!$D:$D, C12, 'Example Weekly Point Data'!$Q:$Q) -> 14 | E12: =D12-$D$4 -> -25 | G12: =C12 -> Bird | H12: =COUNTIFS('Example Weekly Point Data'!G:G,"Won",'Example Weekly Point Data'!D:D,G12) -> 0 | I12: =COUNTIFS('Example Weekly Point Data'!F:F,"No",'Example Weekly Point Data'!D:D,G12) -> 0 | J12: =MINIFS('Example Weekly Point Data'!I:I,'Example Weekly Point Data'!D:D,G12) -> 50
B13: 10 | C13: Hunter | D13: =SUMIF('Example Weekly Point Data'!$D:$D, C13, 'Example Weekly Point Data'!$Q:$Q) -> 0 | E13: =D13-$D$4 -> -39 | G13: =C13 -> Hunter | H13: =COUNTIFS('Example Weekly Point Data'!G:G,"Won",'Example Weekly Point Data'!D:D,G13) -> 0 | I13: =COUNTIFS('Example Weekly Point Data'!F:F,"No",'Example Weekly Point Data'!D:D,G13) -> 0 | J13: =MINIFS('Example Weekly Point Data'!I:I,'Example Weekly Point Data'!D:D,G13) -> 0
B14: 11 | C14: Stefan | D14: =SUMIF('Example Weekly Point Data'!$D:$D, C14, 'Example Weekly Point Data'!$Q:$Q) -> 0 | E14: =D14-$D$4 -> -39 | G14: =C14 -> Stefan | H14: =COUNTIFS('Example Weekly Point Data'!G:G,"Won",'Example Weekly Point Data'!D:D,G14) -> 0 | I14: =COUNTIFS('Example Weekly Point Data'!F:F,"No",'Example Weekly Point Data'!D:D,G14) -> 0 | J14: =MINIFS('Example Weekly Point Data'!I:I,'Example Weekly Point Data'!D:D,G14) -> 0
B15: 12 | D15: =SUMIF('Example Weekly Point Data'!$D:$D, C15, 'Example Weekly Point Data'!$Q:$Q) -> 0 | E15: =D15-$D$4 -> -39 | G15: =C15

Sheet Example Weekly Point Data
A1: Weekly Details | E1: Match Details | L1: Point Details | Q1: Total
A2: Week | B2: Date | C2: Course | D2: Golfer | E2: Partner | F2: Showed | G2: Match Result | H2: Handi cap | I2: Gross Score | J2: Net Score | K2: Putts | L2: Showing Up Points | M2: Match Points | N2: Gross Points | O2: Net Points | P2: Putt Points | Q2: Points
A3: ExW1 | B3: 46096 | C3: Willis Case | D3: Bird | E3: Brandt | F3: Yes | G3: Tied | H3: 17.9 | I3: 50 | J3: =I3-ROUNDUP(H3/2,0) -> 41 | K3: 19 | L3: =IFS(F3="Yes",3,F3="No",0) -> 3 | M3: =IFS(G3="Tied",2,G3="Won",5,G3="Lost",0) -> 2 | N3: 0 | O3: 1 | P3: 2 | Q3: =SUM(L3:P3) -> 8
A4: ExW1 | B4: 46096 | C4: Willis Case | D4: Brandt | E4: Bird | F4: Yes | G4: Tied | H4: 9.1 | I4: 43 | J4: =I4-ROUNDUP(H4/2,0) -> 38 | K4: 18 | L4: =IFS(F4="Yes",3,F4="No",0) -> 3 | M4: =IFS(G4="Tied",2,G4="Won",5,G4="Lost",0) -> 2 | N4: 6 | O4: 3 | P4: 3 | Q4: =SUM(L4:P4) -> 17
A5: ExW1 | B5: 46096 | C5: Willis Case | D5: Bryan | E5: GT | F5: Yes | G5: Lost | H5: 19.1 | I5: 49 | J5: =I5-ROUNDUP(H5/2,0) -> 39 | K5: 18 | L5: =IFS(F5="Yes",3,F5="No",0) -> 3 | M5: =IFS(G5="Tied",2,G5="Won",5,G5="Lost",0) -> 0 | N5: 1 | O5: 2 | P5: 3 | Q5: =SUM(L5:P5) -> 9
A6: ExW1 | B6: 46096 | C6: Willis Case | D6: Cal | E6: Zach | F6: Yes | G6: Tied | H6: 19.1 | I6: 47 | J6: =I6-ROUNDUP(H6/2,0) -> 37 | K6: 16 | L6: =IFS(F6="Yes",3,F6="No",0) -> 3 | M6: =IFS(G6="Tied",2,G6="Won",5,G6="Lost",0) -> 2 | N6: 3 | O6: 4 | P6: 5 | Q6: =SUM(L6:P6) -> 17
A7: ExW1 | B7: 46096 | C7: Willis Case | D7: GT | E7: Bryan | F7: Yes | G7: Lost | H7: 12.1 | I7: 46 | J7: =I7-ROUNDUP(H7/2,0) -> 39 | K7: 17 | L7: =IFS(F7="Yes",3,F7="No",0) -> 3 | M7: =IFS(G7="Tied",2,G7="Won",5,G7="Lost",0) -> 0 | N7: 4 | O7: 2 | P7: 4 | Q7: =SUM(L7:P7) -> 13
A8: ExW1 | B8: 46096 | C8: Willis Case | D8: Jared | E8: Joey | F8: Yes | G8: Won | H8: 28.5 | I8: 52 | J8: =I8-ROUNDUP(H8/2,0) -> 37 | K8: 18 | L8: =IFS(F8="Yes",3,F8="No",0) -> 3 | M8: =IFS(G8="Tied",2,G8="Won",5,G8="Lost",0) -> 5 | N8: 0 | O8: 4 | P8: 3 | Q8: =SUM(L8:P8) -> 15
A9: ExW1 | B9: 46096 | C9: Willis Case | D9: Joe | E9: Handicap | F9: Yes | G9: Won | H9: 17.9 | I9: 48 | J9: =I9-ROUNDUP(H9/2,0) -> 39 | K9: 21 | L9: =IFS(F9="Yes",3,F9="No",0) -> 3 | M9: =IFS(G9="Tied",2,G9="Won",5,G9="Lost",0) -> 5 | N9: 2 | O9: 2 | P9: 0 | Q9: =SUM(L9:P9) -> 12
A10: ExW1 | B10: 46096 | C10: Willis Case | D10: Joey | E10: Jared | F10: Yes | G10: Won | H10: 12.3 | I10: 43 | J10: =I10-ROUNDUP(H10/2,0) -> 36 | K10: 19 | L10: =IFS(F10="Yes",3,F10="No",0) -> 3 | M10: =IFS(G10="Tied",2,G10="Won",5,G10="Lost",0) -> 5 | N10: 6 | O10: 6 | P10: 2 | Q10: =SUM(L10:P10) -> 22
A11: ExW1 | B11: 46096 | C11: Willis Case | D11: Zach | E11: Cal | F11: Yes | G11: Tied | H11: 19.2 | I11: 48 | J11: =I11-ROUNDUP(H11/2,0) -> 38 | K11: 20 | L11: =IFS(F11="Yes",3,F11="No",0) -> 3 | M11: =IFS(G11="Tied",2,G11="Won",5,G11="Lost",0) -> 2 | N11: 2 | O11: 3 | P11: 1 | Q11: =SUM(L11:P11) -> 11
A12: ExW2 | B12: 46104 | C12: City Park | D12: Bird | E12: Cal | F12: Yes | G12: Lost | H12: 17.9 | I12: 50 | J12: =I12-ROUNDUP(H12/2,0) -> 41 | K12: 19 | L12: =IFS(F12="Yes",3,F12="No",0) -> 3 | M12: =IFS(G12="Tied",2,G12="Won",5,G12="Lost",0) -> 0 | N12: 0 | O12: 1 | P12: 2 | Q12: =SUM(L12:P12) -> 6
A13: ExW2 | B13: 46104 | C13: City Park | D13: Brandt | E13: Bryan | F13: Yes | G13: Tied | H13: 9.1 | I13: 43 | J13: =I13-ROUNDUP(H13/2,0) -> 38 | K13: 18 | L13: =IFS(F13="Yes",3,F13="No",0) -> 3 | M13: =IFS(G13="Tied",2,G13="Won",5,G13="Lost",0) -> 2 | N13: 6 | O13: 3 | P13: 3 | Q13: =SUM(L13:P13) -> 17
A14: ExW2 | B14: 46104 | C14: City Park | D14: Bryan | E14: Brandt | F14: Yes | G14: Won | H14: 19.1 | I14: 49 | J14: =I14-ROUNDUP(H14/2,0) -> 39 | K14: 18 | L14: =IFS(F14="Yes",3,F14="No",0) -> 3 | M14: =IFS(G14="Tied",2,G14="Won",5,G14="Lost",0) -> 5 | N14: 1 | O14: 2 | P14: 3 | Q14: =SUM(L14:P14) -> 14
... A16: ExW2 | B16: 46104 | C16: City Park | D16: GT | E16: Joey | F16: Yes | G16: Tied | H16: 12.1 | I16: 46 | J16: =I16-ROUNDUP(H16/2,0) -> 39 | K16: 17 | L16: =IFS(F16="Yes",3,F16="No",0) -> 3 | M16: =IFS(G16="Tied",2,G16="Won",5,G16="Lost",0) -> 2 | N16: 4 | O16: 2 | P16: 4 | Q16: =SUM(L16:P16) -> 15
A17: ExW2 | B17: 46104 | C17: City Park | D17: Jared | E17: n/a | F17: No | G17: Lost | H17: n/a | I17: n/a | J17: n/a | K17: n/a | L17: =IFS(F17="Yes",3,F17="No",0) -> 0 | M17: =IFS(G17="Tied",2,G17="Won",5,G17="Lost",0) -> 0 | N17: 0 | O17: 0 | P17: 0 | Q17: =SUM(L17:P17) -> 0
A18: ExW2 | B18: 46104 | C18: City Park | D18: Joe | E18: Zach | F18: Yes | G18: Tied | H18: 17.9 | I18: 48 | J18: =I18-ROUNDUP(H18/2,0) -> 39 | K18: 21 | L18: =IFS(F18="Yes",3,F18="No",0) -> 3 | M18: =IFS(G18="Tied",2,G18="Won",5,G18="Lost",0) -> 2 | N18: 2 | O18: 2 | P18: 0 | Q18: =SUM(L18:P18) -> 9
A19: ExW2 | B19: 46104 | C19: City Park | D19: Joey | E19: GT | F19: Yes | G19: Lost | H19: 12.3 | I19: 43 | J19: =I19-ROUNDUP(H19/2,0) -> 36 | K19: 19 | L19: =IFS(F19="Yes",3,F19="No",0) -> 3 | M19: =IFS(G19="Tied",2,G19="Won",5,G19="Lost",0) -> 0 | N19: 6 | O19: 6 | P19: 2 | Q19: =SUM(L19:P19) -> 17
A20: ExW2 | B20: 46104 | C20: City Park | D20: Zach | E20: Joey | F20: Yes | G20: Tied | H20: 19.2 | I20: 48 | J20: =I20-ROUNDUP(H20/2,0) -> 38 | K20: 20 | L20: =IFS(F20="Yes",3,F20="No",0) -> 3 | M20: =IFS(G20="Tied",2,G20="Won",5,G20="Lost",0) -> 2 | N20: 2 | O20: 3 | P20: 1 | Q20: =SUM(L20:P20) -> 11

Sheet Weekly Points
B1: Week | C1: Point Category | D1: Bryan | E1: Joey | F1: Cal | G1: Joe | H1: GT | I1: Jared | J1: Brandt | K1: Zach | L1: Bird
B3: Example Week | C3: Showing Up | D3: 3 | E3: 3 | F3: 3 | G3: 3 | H3: 3 | I3: 3 | J3: 3 | K3: 3 | L3: 3
C4: Match Play | D4: - | E4: 5 | F4: 2 | G4: 5 | H4: - | I4: 5 | J4: 2 | K4: 2 | L4: 2
C5: Gross Strokes | D5: 1 | E5: 6 | F5: 3 | G5: 2 | H5: 4 | I5: - | J5: 6 | K5: 2 | L5: -
C6: Net Strokes | D6: 2 | E6: 6 | F6: 4 | G6: 2 | H6: 2 | I6: 4 | J6: 3 | K6: 3 | L6: 1
C7: Putts | D7: 3 | E7: 3 | F7: 5 | G7: - | H7: 4 | I7: 2 | J7: 3 | K7: 1 | L7: 2
C8: Totals | D8: =SUM(D3:D7) -> 9 | E8: =SUM(E3:E7) -> 23 | F8: =SUM(F3:F7) -> 17 | G8: =SUM(G3:G7) -> 12 | H8: =SUM(H3:H7) -> 13 | I8: =SUM(I3:I7) -> 14 | J8: =SUM(J3:J7) -> 17 | K8: =SUM(K3:K7) -> 11 | L8: =SUM(L3:L7) -> 8
B10: Week 1 05/05 | C10: Showing Up
C11: Match Play
C12: Gross Strokes
C13: Net Strokes
C14: Putts
C15: Totals

Sheet Stroke & Putt History
B1: Week | C1: Detail | D1: Bryan | E1: Joey | F1: Cal | G1: Joe | H1: GT | I1: Jared | J1: Brandt | K1: Zach | L1: Bird
B3: Example Week | C3: Handicap | D3: 19.1 | E3: 12.3 | F3: 19.1 | G3: 17.9 | H3: 12.1 | I3: 28.5 | J3: 9.1 | K3: 19.2 | L3: 17.9
C4: Gross Score | D4: 49 | E4: 43 | F4: 47 | G4: 48 | H4: 46 | I4: 52 | J4: 43 | K4: 48 | L4: 50
C5: Net Score | D5: =D4-ROUNDUP((D3/2),0) -> 39 | E5: =E4-ROUNDUP((E3/2),0) -> 36 | F5: =F4-ROUNDUP((F3/2),0) -> 37 | G5: =G4-ROUNDUP((G3/2),0) -> 39 | H5: =H4-ROUNDUP((H3/2),0) -> 39 | I5: =I4-ROUNDUP((I3/2),0) -> 37 | J5: =J4-ROUNDUP((J3/2),0) -> 38 | K5: =K4-ROUNDUP((K3/2),0) -> 38 | L5: =L4-ROUNDUP((L3/2),0) -> 41
C6: Putts | D6: 18 | E6: 18 | F6: 16 | G6: 21 | H6: 17 | I6: 19 | J6: 18 | K6: 20 | L6: 19
B8: Week 1 05/05 | C8: Handicap
C9: Gross Score
C10: Net Score
C11: Putts
