Workbook

Sheet Schedule
A1: Date | B1: Course | C1: Time 1 | D1: Time 2 | E1: Time 3
A2: 46147 | B2: Fossil Trace | C2: n/a | D2: n/a | E2: n/a
A3: 46154 | B3: Overland | C3: 0.73611111 | D3: 0.74305556 | E3: 0.75
A4: 46161 | B4: Broken Tee | C4: 0.72222222 | D4: 0.72916667 | E4: 0.73611111 | F4: 510 | G4: 520 | H4: 530 | I4: IndianTree
A5: 46168 | B5: Overland | C5: 0.73611111 | D5: 0.74305556 | E5: 0.75
A6: 46175
A7: 46182
A8: 46189
A9: 46196
A10: 46203
A11: 46210
A12: 46217
A13: 46224
A14: 46231
A15: 46238
A16: 46245
A17: 46252
... A23: 46294

Sheet Leaderboard
B2: Leaderboard
B3: Pos. | C3: Golfer | D3: Points | E3: Behind | G3: Golfer | H3: Points + Beer Points | I3: Match Wins | J3: Blank Weeks | K3: Lowest Score
B4: 1 | C4: Zach | D4: =SUMIF('Weekly Point Data'!$D:$D, C4, 'Weekly Point Data'!$S:$S) -> 23 | E4: 0 | G4: Zach | H4: =SUMIF('Weekly Point Data'!$D:$D, G4, 'Weekly Point Data'!$S:$S)+SUMIF('Weekly Point Data'!$D:$D, G4, 'Weekly Point Data'!$F:$F) -> 23 | I4: =COUNTIFS('Weekly Point Data'!I:I,"Won",'Weekly Point Data'!D:D,G4) -> 1 | J4: =COUNTIFS('Weekly Point Data'!E:E,"No",'Weekly Point Data'!D:D,G4) -> 0 | K4: =MINIFS('Weekly Point Data'!K:K,'Weekly Point Data'!D:D,G4) -> 40
B5: 2 | C5: Bird | D5: =SUMIF('Weekly Point Data'!$D:$D, C5, 'Weekly Point Data'!$S:$S) -> 16 | E5: =D5-$D$4 -> -7 | G5: Bird | H5: =SUMIF('Weekly Point Data'!$D:$D, G5, 'Weekly Point Data'!$S:$S)+SUMIF('Weekly Point Data'!$D:$D, G5, 'Weekly Point Data'!$F:$F) -> 16 | I5: =COUNTIFS('Weekly Point Data'!I:I,"Won",'Weekly Point Data'!D:D,G5) -> 1 | J5: =COUNTIFS('Weekly Point Data'!E:E,"No",'Weekly Point Data'!D:D,G5) -> 0 | K5: =MINIFS('Weekly Point Data'!K:K,'Weekly Point Data'!D:D,G5) -> 42
B6: 3 | C6: Joe | D6: =SUMIF('Weekly Point Data'!$D:$D, C6, 'Weekly Point Data'!$S:$S) -> 14 | E6: =D6-$D$4 -> -9 | G6: Joe | H6: =SUMIF('Weekly Point Data'!$D:$D, G6, 'Weekly Point Data'!$S:$S)+SUMIF('Weekly Point Data'!$D:$D, G6, 'Weekly Point Data'!$F:$F) -> 14 | I6: =COUNTIFS('Weekly Point Data'!I:I,"Won",'Weekly Point Data'!D:D,G6) -> 0 | J6: =COUNTIFS('Weekly Point Data'!E:E,"No",'Weekly Point Data'!D:D,G6) -> 0 | K6: =MINIFS('Weekly Point Data'!K:K,'Weekly Point Data'!D:D,G6) -> 42
B7: 4 | C7: Bryan | D7: =SUMIF('Weekly Point Data'!$D:$D, C7, 'Weekly Point Data'!$S:$S) -> 12 | E7: =D7-$D$4 -> -11 | G7: Bryan | H7: =SUMIF('Weekly Point Data'!$D:$D, G7, 'Weekly Point Data'!$S:$S)+SUMIF('Weekly Point Data'!$D:$D, G7, 'Weekly Point Data'!$F:$F) -> 12 | I7: =COUNTIFS('Weekly Point Data'!I:I,"Won",'Weekly Point Data'!D:D,G7) -> 0 | J7: =COUNTIFS('Weekly Point Data'!E:E,"No",'Weekly Point Data'!D:D,G7) -> 0 | K7: =MINIFS('Weekly Point Data'!K:K,'Weekly Point Data'!D:D,G7) -> 42
B8: 5 | C8: GT | D8: =SUMIF('Weekly Point Data'!$D:$D, C8, 'Weekly Point Data'!$S:$S) -> 11 | E8: =D8-$D$4 -> -12 | G8: GT | H8: =SUMIF('Weekly Point Data'!$D:$D, G8, 'Weekly Point Data'!$S:$S)+SUMIF('Weekly Point Data'!$D:$D, G8, 'Weekly Point Data'!$F:$F) -> 11 | I8: =COUNTIFS('Weekly Point Data'!I:I,"Won",'Weekly Point Data'!D:D,G8) -> 0 | J8: =COUNTIFS('Weekly Point Data'!E:E,"No",'Weekly Point Data'!D:D,G8) -> 0 | K8: =MINIFS('Weekly Point Data'!K:K,'Weekly Point Data'!D:D,G8) -> 44
B9: 6 | C9: Joey | D9: =SUMIF('Weekly Point Data'!$D:$D, C9, 'Weekly Point Data'!$S:$S) -> 7 | E9: =D9-$D$4 -> -16 | G9: John | H9: =SUMIF('Weekly Point Data'!$D:$D, G9, 'Weekly Point Data'!$S:$S)+SUMIF('Weekly Point Data'!$D:$D, G9, 'Weekly Point Data'!$F:$F) -> 9 | I9: =COUNTIFS('Weekly Point Data'!I:I,"Won",'Weekly Point Data'!D:D,G9) -> 0 | J9: =COUNTIFS('Weekly Point Data'!E:E,"No",'Weekly Point Data'!D:D,G9) -> 0 | K9: =MINIFS('Weekly Point Data'!K:K,'Weekly Point Data'!D:D,G9) -> 60
B10: 7 | C10: Brandt | D10: =SUMIF('Weekly Point Data'!$D:$D, C10, 'Weekly Point Data'!$S:$S) -> 7 | E10: =D10-$D$4 -> -16 | G10: Brandt | H10: =SUMIF('Weekly Point Data'!$D:$D, G10, 'Weekly Point Data'!$S:$S)+SUMIF('Weekly Point Data'!$D:$D, G10, 'Weekly Point Data'!$F:$F) -> 7 | I10: =COUNTIFS('Weekly Point Data'!I:I,"Won",'Weekly Point Data'!D:D,G10) -> 0 | J10: =COUNTIFS('Weekly Point Data'!E:E,"No",'Weekly Point Data'!D:D,G10) -> 0 | K10: =MINIFS('Weekly Point Data'!K:K,'Weekly Point Data'!D:D,G10) -> 51
B11: 9 | C11: John | D11: =SUMIF('Weekly Point Data'!$D:$D, C11, 'Weekly Point Data'!$S:$S) -> 5 | E11: =D11-$D$4 -> -18 | G11: Joey | H11: =SUMIF('Weekly Point Data'!$D:$D, G11, 'Weekly Point Data'!$S:$S)+SUMIF('Weekly Point Data'!$D:$D, G11, 'Weekly Point Data'!$F:$F) -> 7 | I11: =COUNTIFS('Weekly Point Data'!I:I,"Won",'Weekly Point Data'!D:D,G11) -> 0 | J11: =COUNTIFS('Weekly Point Data'!E:E,"No",'Weekly Point Data'!D:D,G11) -> 0 | K11: =MINIFS('Weekly Point Data'!K:K,'Weekly Point Data'!D:D,G11) -> 44
B12: 9 | C12: Hunter | D12: =SUMIF('Weekly Point Data'!$D:$D, C12, 'Weekly Point Data'!$S:$S) -> 4 | E12: =D12-$D$4 -> -19 | G12: Hunter | H12: =SUMIF('Weekly Point Data'!$D:$D, G12, 'Weekly Point Data'!$S:$S)+SUMIF('Weekly Point Data'!$D:$D, G12, 'Weekly Point Data'!$F:$F) -> 4 | I12: =COUNTIFS('Weekly Point Data'!I:I,"Won",'Weekly Point Data'!D:D,G12) -> 0 | J12: =COUNTIFS('Weekly Point Data'!E:E,"No",'Weekly Point Data'!D:D,G12) -> 0 | K12: =MINIFS('Weekly Point Data'!K:K,'Weekly Point Data'!D:D,G12) -> 55
B13: 10 | C13: Jared | D13: =SUMIF('Weekly Point Data'!$D:$D, C13, 'Weekly Point Data'!$S:$S) -> 0 | E13: =D13-$D$4 -> -23 | G13: Jared | H13: =SUMIF('Weekly Point Data'!$D:$D, G13, 'Weekly Point Data'!$S:$S)+SUMIF('Weekly Point Data'!$D:$D, G13, 'Weekly Point Data'!$F:$F) -> 0 | I13: =COUNTIFS('Weekly Point Data'!I:I,"Won",'Weekly Point Data'!D:D,G13) -> 0 | J13: =COUNTIFS('Weekly Point Data'!E:E,"No",'Weekly Point Data'!D:D,G13) -> 1 | K13: =MINIFS('Weekly Point Data'!K:K,'Weekly Point Data'!D:D,G13) -> 0
B14: 11 | C14: Stefan | D14: =SUMIF('Weekly Point Data'!$D:$D, C14, 'Weekly Point Data'!$S:$S) -> 0 | E14: =D14-$D$4 -> -23 | G14: Stefan | H14: =SUMIF('Weekly Point Data'!$D:$D, G14, 'Weekly Point Data'!$S:$S)+SUMIF('Weekly Point Data'!$D:$D, G14, 'Weekly Point Data'!$F:$F) -> 0 | I14: =COUNTIFS('Weekly Point Data'!I:I,"Won",'Weekly Point Data'!D:D,G14) -> 0 | J14: =COUNTIFS('Weekly Point Data'!E:E,"No",'Weekly Point Data'!D:D,G14) -> 1 | K14: =MINIFS('Weekly Point Data'!K:K,'Weekly Point Data'!D:D,G14) -> 0

Sheet Weekly Point Data
A1: Weekly Details | E1: Match Details | N1: Point Details | S1: Total
A2: Week | B2: Date | C2: Course | D2: Golfer | E2: Showed | F2: Beers | G2: Paid | H2: Partner | I2: Match Result | J2: HC | K2: Gross Score | L2: Putts | M2: Net Score | N2: Showing Up Points | O2: Match Points | P2: Gross Points | Q2: Net Points | R2: Putt Points | S2: Points
A3: W02 | B3: 46154 | C3: Overland | D3: Zach | E3: unk | H3: - | I3: n/a | N3: =IFS(E3="Yes",3,E3="No",0,E3="Confirmed",3,E3="unk",0) -> 0 | O3: =IFS(I3="Tied",2,I3="Won",5,I3="Lost",0,I3="n/a",0) -> 0 | P3: 0 | Q3: 0 | R3: 0 | S3: =SUM(N3:R3) -> 0
A4: W02 | B4: 46154 | C4: Overland | D4: Joe | E4: unk | H4: - | I4: n/a | N4: =IFS(E4="Yes",3,E4="No",0,E4="Confirmed",3,E4="unk",0) -> 0 | O4: =IFS(I4="Tied",2,I4="Won",5,I4="Lost",0,I4="n/a",0) -> 0 | P4: 0 | Q4: 0 | R4: 0 | S4: =SUM(N4:R4) -> 0
A5: W02 | B5: 46154 | C5: Overland | D5: Bird | E5: unk | H5: - | I5: n/a | N5: =IFS(E5="Yes",3,E5="No",0,E5="Confirmed",3,E5="unk",0) -> 0 | O5: =IFS(I5="Tied",2,I5="Won",5,I5="Lost",0,I5="n/a",0) -> 0 | P5: 0 | Q5: 0 | R5: 0 | S5: =SUM(N5:R5) -> 0
A6: W02 | B6: 46154 | C6: Overland | D6: Bryan | E6: unk | H6: - | I6: n/a | N6: =IFS(E6="Yes",3,E6="No",0,E6="Confirmed",3,E6="unk",0) -> 0 | O6: =IFS(I6="Tied",2,I6="Won",5,I6="Lost",0,I6="n/a",0) -> 0 | P6: 0 | Q6: 0 | R6: 0 | S6: =SUM(N6:R6) -> 0
A7: W02 | B7: 46154 | C7: Overland | D7: GT | E7: unk | H7: - | I7: n/a | N7: =IFS(E7="Yes",3,E7="No",0,E7="Confirmed",3,E7="unk",0) -> 0 | O7: =IFS(I7="Tied",2,I7="Won",5,I7="Lost",0,I7="n/a",0) -> 0 | P7: 0 | Q7: 0 | R7: 0 | S7: =SUM(N7:R7) -> 0
A8: W02 | B8: 46154 | C8: Overland | D8: Joey | E8: unk | H8: - | I8: n/a | N8: =IFS(E8="Yes",3,E8="No",0,E8="Confirmed",3,E8="unk",0) -> 0 | O8: =IFS(I8="Tied",2,I8="Won",5,I8="Lost",0,I8="n/a",0) -> 0 | P8: 0 | Q8: 0 | R8: 0 | S8: =SUM(N8:R8) -> 0
A9: W02 | B9: 46154 | C9: Overland | D9: Hunter | E9: unk | H9: - | I9: n/a | N9: =IFS(E9="Yes",3,E9="No",0,E9="Confirmed",3,E9="unk",0) -> 0 | O9: =IFS(I9="Tied",2,I9="Won",5,I9="Lost",0,I9="n/a",0) -> 0 | P9: 0 | Q9: 0 | R9: 0 | S9: =SUM(N9:R9) -> 0
A10: W02 | B10: 46154 | C10: Overland | D10: John | E10: unk | H10: - | I10: n/a | N10: =IFS(E10="Yes",3,E10="No",0,E10="Confirmed",3,E10="unk",0) -> 0 | O10: =IFS(I10="Tied",2,I10="Won",5,I10="Lost",0,I10="n/a",0) -> 0 | P10: 0 | Q10: 0 | R10: 0 | S10: =SUM(N10:R10) -> 0
A11: W02 | B11: 46154 | C11: Overland | D11: Brandt | E11: unk | H11: - | I11: n/a | N11: =IFS(E11="Yes",3,E11="No",0,E11="Confirmed",3,E11="unk",0) -> 0 | O11: =IFS(I11="Tied",2,I11="Won",5,I11="Lost",0,I11="n/a",0) -> 0 | P11: 0 | Q11: 0 | R11: 0 | S11: =SUM(N11:R11) -> 0
A12: W02 | B12: 46154 | C12: Overland | D12: Jared | E12: unk | H12: - | I12: n/a | N12: =IFS(E12="Yes",3,E12="No",0,E12="Confirmed",3,E12="unk",0) -> 0 | O12: =IFS(I12="Tied",2,I12="Won",5,I12="Lost",0,I12="n/a",0) -> 0 | P12: 0 | Q12: 0 | R12: 0 | S12: =SUM(N12:R12) -> 0
A13: W02 | B13: 46154 | C13: Overland | D13: Stefan | E13: unk | H13: - | I13: n/a | N13: =IFS(E13="Yes",3,E13="No",0,E13="Confirmed",3,E13="unk",0) -> 0 | O13: =IFS(I13="Tied",2,I13="Won",5,I13="Lost",0,I13="n/a",0) -> 0 | P13: 0 | Q13: 0 | R13: 0 | S13: =SUM(N13:R13) -> 0
A14: W01 | B14: 46154 | C14: Overland | D14: Zach | E14: Confirmed | G14: Yes | H14: - | I14: Won | J14: 21 | K14: 40 | L14: 13 | M14: =K14-ROUNDUP(J14/2,0) -> 29 | N14: =IFS(E14="Yes",3,E14="No",0,E14="Confirmed",3,E14="unk",0) -> 3 | O14: =IFS(I14="Tied",2,I14="Won",5,I14="Lost",0,I14="n/a",0) -> 5 | P14: 6 | Q14: 5 | R14: 4 | S14: =SUM(N14:R14) -> 23
A15: W01 | B15: 46154 | C15: Overland | D15: John | E15: Confirmed | F15: 4 | G15: Yes | H15: - | I15: Tied | J15: 28 | K15: 60 | L15: 18 | M15: =K15-ROUNDUP(J15/2,0) -> 46 | N15: =IFS(E15="Yes",3,E15="No",0,E15="Confirmed",3,E15="unk",0) -> 3 | O15: =IFS(I15="Tied",2,I15="Won",5,I15="Lost",0,I15="n/a",0) -> 2 | P15: 0 | Q15: 0 | R15: 0 | S15: =SUM(N15:R15) -> 5
A16: W01 | B16: 46154 | C16: Overland | D16: Joe | E16: Confirmed | G16: Yes | H16: - | I16: Tied | J16: 17.9 | K16: 42 | L16: 17 | M16: =K16-ROUNDUP(J16/2,0) -> 33 | N16: =IFS(E16="Yes",3,E16="No",0,E16="Confirmed",3,E16="unk",0) -> 3 | O16: =IFS(I16="Tied",2,I16="Won",5,I16="Lost",0,I16="n/a",0) -> 2 | P16: 4 | Q16: 4 | R16: 1 | S16: =SUM(N16:R16) -> 14
A17: W01 | B17: 46154 | C17: Overland | D17: Bird | E17: Confirmed | G17: Yes | H17: - | I17: Won | J17: 16.8 | K17: 42 | L17: 21 | M17: =K17-ROUNDUP(J17/2,0) -> 33 | N17: =IFS(E17="Yes",3,E17="No",0,E17="Confirmed",3,E17="unk",0) -> 3 | O17: =IFS(I17="Tied",2,I17="Won",5,I17="Lost",0,I17="n/a",0) -> 5 | P17: 4 | Q17: 4 | R17: 0 | S17: =SUM(N17:R17) -> 16
A18: W01 | B18: 46154 | C18: Overland | D18: Bryan | E18: Confirmed | G18: Yes | H18: - | I18: Tied | J18: 13.9 | K18: 42 | L18: 18 | M18: =K18-ROUNDUP(J18/2,0) -> 35 | N18: =IFS(E18="Yes",3,E18="No",0,E18="Confirmed",3,E18="unk",0) -> 3 | O18: =IFS(I18="Tied",2,I18="Won",5,I18="Lost",0,I18="n/a",0) -> 2 | P18: 4 | Q18: 3 | R18: 0 | S18: =SUM(N18:R18) -> 12
A19: W01 | B19: 46154 | C19: Overland | D19: GT | E19: Confirmed | G19: Yes | H19: - | I19: Lost | J19: 12.7 | K19: 44 | L19: 15 | M19: =K19-ROUNDUP(J19/2,0) -> 37 | N19: =IFS(E19="Yes",3,E19="No",0,E19="Confirmed",3,E19="unk",0) -> 3 | O19: =IFS(I19="Tied",2,I19="Won",5,I19="Lost",0,I19="n/a",0) -> 0 | P19: 3 | Q19: 2 | R19: 3 | S19: =SUM(N19:R19) -> 11
A20: W01 | B20: 46154 | C20: Overland | D20: Joey | E20: Confirmed | G20: Yes | H20: - | I20: Lost | J20: 10.9 | K20: 44 | L20: 18 | M20: =K20-ROUNDUP(J20/2,0) -> 38 | N20: =IFS(E20="Yes",3,E20="No",0,E20="Confirmed",3,E20="unk",0) -> 3 | O20: =IFS(I20="Tied",2,I20="Won",5,I20="Lost",0,I20="n/a",0) -> 0 | P20: 3 | Q20: 1 | R20: 0 | S20: =SUM(N20:R20) -> 7
A21: W01 | B21: 46154 | C21: Overland | D21: Hunter | E21: Confirmed | G21: Yes | H21: - | I21: Lost | J21: 28 | K21: 55 | L21: 18 | M21: =K21-ROUNDUP(J21/2,0) -> 41 | N21: =IFS(E21="Yes",3,E21="No",0,E21="Confirmed",3,E21="unk",0) -> 3 | O21: =IFS(I21="Tied",2,I21="Won",5,I21="Lost",0,I21="n/a",0) -> 0 | P21: 1 | Q21: 0 | R21: 0 | S21: =SUM(N21:R21) -> 4
A22: W01 | B22: 46154 | C22: Overland | D22: Brandt | E22: Confirmed | G22: Yes | H22: - | I22: Lost | J22: 9.1 | K22: 51 | L22: 16 | M22: =K22-ROUNDUP(J22/2,0) -> 46 | N22: =IFS(E22="Yes",3,E22="No",0,E22="Confirmed",3,E22="unk",0) -> 3 | O22: =IFS(I22="Tied",2,I22="Won",5,I22="Lost",0,I22="n/a",0) -> 0 | P22: 2 | Q22: 0 | R22: 2 | S22: =SUM(N22:R22) -> 7
A23: W01 | B23: 46154 | C23: Overland | D23: Jared | E23: No | H23: - | I23: n/a | J23: - | K23: - | L23: - | M23: - | N23: =IFS(E23="Yes",3,E23="No",0,E23="Confirmed",3,E23="unk",0) -> 0 | O23: =IFS(I23="Tied",2,I23="Won",5,I23="Lost",0,I23="n/a",0) -> 0 | P23: 0 | Q23: 0 | R23: 0 | S23: =SUM(N23:R23) -> 0
A24: W01 | B24: 46154 | C24: Overland | D24: Stefan | E24: No | H24: - | I24: n/a | J24: - | K24: - | L24: - | M24: - | N24: =IFS(E24="Yes",3,E24="No",0,E24="Confirmed",3,E24="unk",0) -> 0 | O24: =IFS(I24="Tied",2,I24="Won",5,I24="Lost",0,I24="n/a",0) -> 0 | P24: 0 | Q24: 0 | R24: 0 | S24: =SUM(N24:R24) -> 0

Sheet Match Generator
B2: 5/19 Weekly Matches Indian Tree | H2: 1v1v1 strokes given for match play
B22: 2v2
D23: vs.
B24: {=ROUNDUP(XLOOKUP(B23,'Match Generator'!$B$36:$B$46,'Match Generator'!$C$36:$C$46)/2,0)} -> #N/A | C24: {=ROUNDUP(XLOOKUP(C23,'Match Generator'!$B$36:$B$46,'Match Generator'!$C$36:$C$46)/2,0)} -> #N/A | D24: Strokes | E24: {=ROUNDUP(XLOOKUP(E23,'Match Generator'!$B$36:$B$46,'Match Generator'!$C$36:$C$46)/2,0)} -> #N/A | F24: {=ROUNDUP(XLOOKUP(F23,'Match Generator'!$B$36:$B$46,'Match Generator'!$C$36:$C$46)/2,0)} -> #N/A
B25: Team Handicap: | C25: =B24+C24 -> #N/A | D25: =ABS(C25-F25) -> #N/A | E25: Team Handicap: | F25: =E24+F24 -> #N/A
B27: 1v1
D28: vs.
B29: {=ROUNDUP(XLOOKUP(B28,'Match Generator'!$B$36:$B$46,'Match Generator'!$C$36:$C$46)/2,0)} -> #N/A | D29: =ABS(B29-E29) -> #N/A | E29: {=ROUNDUP(XLOOKUP(E28,'Match Generator'!$B$36:$B$46,'Match Generator'!$C$36:$C$46)/2,0)} -> #N/A
B31: 1v1v1 | H31: {=INDEX(B32:F32, MATCH(MIN(B33:F33), B33:F33, 0))} -> #N/A | I31: gives:
C32: vs. | E32: vs. | H32: {=INDEX(B32:F32, MATCH(MEDIAN(B33:F33), B33:F33, 0))} -> #N/A | I32: =MEDIAN(B32:F33)-MIN(B32:F33) -> #N/A | J32: strokes | L32: {=INDEX(B32:F32, MATCH(MEDIAN(B33:F33), B33:F33, 0))} -> #N/A | M32: gives:
B33: {=ROUNDUP(XLOOKUP(B32,'Match Generator'!$B$36:$B$46,'Match Generator'!$C$36:$C$46)/2,0)} -> #N/A | D33: {=ROUNDUP(XLOOKUP(D32,'Match Generator'!$B$36:$B$46,'Match Generator'!$C$36:$C$46)/2,0)} -> #N/A | F33: {=ROUNDUP(XLOOKUP(F32,'Match Generator'!$B$36:$B$46,'Match Generator'!$C$36:$C$46)/2,0)} -> #N/A | H33: {=INDEX(B32:F32, MATCH(MAX(B33:F33), B33:F33, 0))} -> #N/A | I33: =MAX(B32:F33)-MIN(B32:F33) -> #N/A | J33: strokes | L33: {=INDEX(B32:F32, MATCH(MAX(B33:F33), B33:F33, 0))} -> #N/A | M33: =MAX(B32:F33)-MEDIAN(B32:F33) -> #N/A | N33: strokes
C35: https://wheelofnames.com
B36: Bird | C36: 16.8 | D36: Confirmed
B37: Brandt | C37: 9.1 | D37: Confirmed
B38: Bryan | C38: 13.9 | D38: Confirmed
B39: GT | C39: 12.7 | D39: Confirmed
B40: Hunter | C40: 28 | D40: Confirmed
B41: Joe | C41: 17.9 | D41: Confirmed
B42: Joey | C42: 10.9 | D42: Confirmed
B43: John | C43: 28 | D43: Confirmed
B44: Zach | C44: 21 | D44: Confirmed
B45: Jared | C45: 28 | D45: No
B46: Stefan | C46: - | D46: No
B49: Course | C49: Link | D49: Rank
B50: Indian Tree | C50: https://indiantree.cps.golf/onlineresweb/search-teetime?TeeOffTimeMin=0&TeeOffTimeMax=23 | D50: A
B51: Fox Hollow | C51: https://app.membersports.com/tee-times/3703/20589/0 | D51: A
B52: West Woods | D52: A
B53: Broken Tee | D53: A
B54: Overland | D54: A
B55: Willis Case | C55: https://app.membersports.com/tee-times/3629/20573/1
B56: Fossil Trace | C56: https://fossiltrace.cps.golf/onlineresweb/search-teetime?TeeOffTimeMin=0&TeeOffTimeMax=23.999722222222225 | D56: A
B57: Legacy Ridge | C57: https://cityofwestminster.cps.golf/onlineresweb/search-teetime?TeeOffTimeMin=0&TeeOffTimeMax=23
B58: Walnut Creet | C58: https://cityofwestminster.cps.golf/onlineresweb/search-teetime?TeeOffTimeMin=0&TeeOffTimeMax=23
B59: Foothills | C59: https://app.membersports.com/tee-times/3697/4758/0
B60: GVR | C60: https://greenvalleyranch.cps.golf/onlineresweb/search-teetime?TeeOffTimeMin=0&TeeOffTimeMax=23
B61: Heather Ridge | C61: https://heatherridge.ezlinksgolf.com/index.html#/search
B62: Homestead | C62: https://app.membersports.com/tee-times/3807/4902/0

Sheet 0512 Match Generator
B2: 5/12 Weekly Matches | H2: 1v1v1 strokes given for match play
B5: 0.73611111 | H5: {=INDEX(B6:F6, MATCH(MIN(B7:F7), B7:F7, 0))} -> Bryan | I5: gives:
B6: Bryan | C6: vs. | D6: Joe | E6: vs. | F6: John | H6: {=INDEX(B6:F6, MATCH(MEDIAN(B7:F7), B7:F7, 0))} -> Joe | I6: =MEDIAN(B6:F7)-MIN(B6:F7) -> 2 | J6: strokes | L6: {=INDEX(B6:F6, MATCH(MEDIAN(B7:F7), B7:F7, 0))} -> Joe | M6: gives:
B7: {=ROUNDUP(XLOOKUP(B6,'0512 Match Generator'!$B$47:$B$57,'0512 Match Generator'!$C$47:$C$57)/2,0)} -> 7 | D7: {=ROUNDUP(XLOOKUP(D6,'0512 Match Generator'!$B$47:$B$57,'0512 Match Generator'!$C$47:$C$57)/2,0)} -> 9 | F7: {=ROUNDUP(XLOOKUP(F6,'0512 Match Generator'!$B$47:$B$57,'0512 Match Generator'!$C$47:$C$57)/2,0)} -> 14 | H7: {=INDEX(B6:F6, MATCH(MAX(B7:F7), B7:F7, 0))} -> John | I7: =MAX(B6:F7)-MIN(B6:F7) -> 7 | J7: strokes | L7: {=INDEX(B6:F6, MATCH(MAX(B7:F7), B7:F7, 0))} -> John | M7: =MAX(B6:F7)-MEDIAN(B6:F7) -> 5 | N7: strokes
B9: 0.74305556 | H9: {=INDEX(B10:F10, MATCH(MIN(B11:F11), B11:F11, 0))} -> Brandt | I9: gives:
B10: Brandt | C10: vs. | D10: Bird | E10: vs. | F10: Hunter | H10: {=INDEX(B10:F10, MATCH(MEDIAN(B11:F11), B11:F11, 0))} -> Bird | I10: =MEDIAN(B10:F11)-MIN(B10:F11) -> 4 | J10: strokes | L10: {=INDEX(B10:F10, MATCH(MEDIAN(B11:F11), B11:F11, 0))} -> Bird | M10: gives:
B11: {=ROUNDUP(XLOOKUP(B10,'0512 Match Generator'!$B$47:$B$57,'0512 Match Generator'!$C$47:$C$57)/2,0)} -> 5 | D11: {=ROUNDUP(XLOOKUP(D10,'0512 Match Generator'!$B$47:$B$57,'0512 Match Generator'!$C$47:$C$57)/2,0)} -> 9 | F11: {=ROUNDUP(XLOOKUP(F10,'0512 Match Generator'!$B$47:$B$57,'0512 Match Generator'!$C$47:$C$57)/2,0)} -> 14 | H11: {=INDEX(B10:F10, MATCH(MAX(B11:F11), B11:F11, 0))} -> Hunter | I11: =MAX(B10:F11)-MIN(B10:F11) -> 9 | J11: strokes | L11: {=INDEX(B10:F10, MATCH(MAX(B11:F11), B11:F11, 0))} -> Hunter | M11: =MAX(B10:F11)-MEDIAN(B10:F11) -> 5 | N11: strokes
B13: 0.75 | H13: {=INDEX(B14:F14, MATCH(MIN(B15:F15), B15:F15, 0))} -> Joey | I13: gives:
B14: GT | C14: vs. | D14: Zach | E14: vs. | F14: Joey | H14: {=INDEX(B14:F14, MATCH(MEDIAN(B15:F15), B15:F15, 0))} -> GT | I14: =MEDIAN(B14:F15)-MIN(B14:F15) -> 1 | J14: strokes | L14: {=INDEX(B14:F14, MATCH(MEDIAN(B15:F15), B15:F15, 0))} -> GT | M14: gives:
B15: {=ROUNDUP(XLOOKUP(B14,'0512 Match Generator'!$B$47:$B$57,'0512 Match Generator'!$C$47:$C$57)/2,0)} -> 7 | D15: {=ROUNDUP(XLOOKUP(D14,'0512 Match Generator'!$B$47:$B$57,'0512 Match Generator'!$C$47:$C$57)/2,0)} -> 11 | F15: {=ROUNDUP(XLOOKUP(F14,'0512 Match Generator'!$B$47:$B$57,'0512 Match Generator'!$C$47:$C$57)/2,0)} -> 6 | H15: {=INDEX(B14:F14, MATCH(MAX(B15:F15), B15:F15, 0))} -> Zach | I15: =MAX(B14:F15)-MIN(B14:F15) -> 5 | J15: strokes | L15: {=INDEX(B14:F14, MATCH(MAX(B15:F15), B15:F15, 0))} -> Zach | M15: =MAX(B14:F15)-MEDIAN(B14:F15) -> 4 | N15: strokes
B33: 2v2
D34: vs.
B35: {=ROUNDUP(XLOOKUP(B34,'0512 Match Generator'!$B$47:$B$57,'0512 Match Generator'!$C$47:$C$57)/2,0)} -> #N/A | C35: {=ROUNDUP(XLOOKUP(C34,'0512 Match Generator'!$B$47:$B$57,'0512 Match Generator'!$C$47:$C$57)/2,0)} -> #N/A | D35: Strokes | E35: {=ROUNDUP(XLOOKUP(E34,'0512 Match Generator'!$B$47:$B$57,'0512 Match Generator'!$C$47:$C$57)/2,0)} -> #N/A | F35: {=ROUNDUP(XLOOKUP(F34,'0512 Match Generator'!$B$47:$B$57,'0512 Match Generator'!$C$47:$C$57)/2,0)} -> #N/A
B36: Team Handicap: | C36: =B35+C35 -> #N/A | D36: =ABS(C36-F36) -> #N/A | E36: Team Handicap: | F36: =E35+F35 -> #N/A
B38: 1v1
D39: vs.
B40: {=ROUNDUP(XLOOKUP(B39,'0512 Match Generator'!$B$47:$B$57,'0512 Match Generator'!$C$47:$C$57)/2,0)} -> #N/A | D40: =ABS(B40-E40) -> #N/A | E40: {=ROUNDUP(XLOOKUP(E39,'0512 Match Generator'!$B$47:$B$57,'0512 Match Generator'!$C$47:$C$57)/2,0)} -> #N/A
B42: 1v1v1 | H42: {=INDEX(B43:F43, MATCH(MIN(B44:F44), B44:F44, 0))} -> #N/A | I42: gives:
C43: vs. | E43: vs. | H43: {=INDEX(B43:F43, MATCH(MEDIAN(B44:F44), B44:F44, 0))} -> #N/A | I43: =MEDIAN(B43:F44)-MIN(B43:F44) -> #N/A | J43: strokes | L43: {=INDEX(B43:F43, MATCH(MEDIAN(B44:F44), B44:F44, 0))} -> #N/A | M43: gives:
B44: {=ROUNDUP(XLOOKUP(B43,'0512 Match Generator'!$B$47:$B$57,'0512 Match Generator'!$C$47:$C$57)/2,0)} -> #N/A | D44: {=ROUNDUP(XLOOKUP(D43,'0512 Match Generator'!$B$47:$B$57,'0512 Match Generator'!$C$47:$C$57)/2,0)} -> #N/A | F44: {=ROUNDUP(XLOOKUP(F43,'0512 Match Generator'!$B$47:$B$57,'0512 Match Generator'!$C$47:$C$57)/2,0)} -> #N/A | H44: {=INDEX(B43:F43, MATCH(MAX(B44:F44), B44:F44, 0))} -> #N/A | I44: =MAX(B43:F44)-MIN(B43:F44) -> #N/A | J44: strokes | L44: {=INDEX(B43:F43, MATCH(MAX(B44:F44), B44:F44, 0))} -> #N/A | M44: =MAX(B43:F44)-MEDIAN(B43:F44) -> #N/A | N44: strokes
C46: https://wheelofnames.com
B47: Bird | C47: 16.8 | D47: Confirmed
B48: Brandt | C48: 9.1 | D48: Confirmed
B49: Bryan | C49: 13.9 | D49: Confirmed
B50: GT | C50: 12.7 | D50: Confirmed
B51: Hunter | C51: 28 | D51: Confirmed
B52: Joe | C52: 17.9 | D52: Confirmed
B53: Joey | C53: 10.9 | D53: Confirmed
B54: John | C54: 28 | D54: Confirmed
B55: Zach | C55: 21 | D55: Confirmed
B56: Jared | C56: 28 | D56: No
B57: Stefan | C57: - | D57: No
B60: Course | C60: Link | D60: Rank
B61: Indian Tree | C61: https://indiantree.cps.golf/onlineresweb/search-teetime?TeeOffTimeMin=0&TeeOffTimeMax=23 | D61: A
B62: Fox Hollow | C62: https://app.membersports.com/tee-times/3703/20589/0 | D62: A
B63: West Woods | D63: A
B64: Broken Tee | D64: A
B65: Overland | D65: A
B66: Willis Case | C66: https://app.membersports.com/tee-times/3629/20573/1
B67: Fossil Trace | C67: https://fossiltrace.cps.golf/onlineresweb/search-teetime?TeeOffTimeMin=0&TeeOffTimeMax=23.999722222222225 | D67: A
...

Sheet Scoring Rules
B2: https://docs.google.com/document/d/1zjUmxKJ9ZaPkMGQOF_XHnWdDfx2B-lGk6ijITGp1UqQ/edit?tab=t.0 | E2: Rank | F2: Gross Strokes | G2: Net Strokes | H2: Putts
B3: Showing Up | E3: 1 | F3: 6 | G3: 5 | H3: 4
B4: Showed | C4: 3 | E4: 2 | F4: 4 | G4: 4 | H4: 3
B5: No Show | C5: 0 | E5: 3 | F5: 3 | G5: 3 | H5: 2
E6: 4 | F6: 2 | G6: 2 | H6: 1
B7: Match Play | E7: 5 | F7: 1 | G7: 1 | H7: 0
B8: Wiiners | C8: 5 | E8: 6+ | F8: 0 | G8: 0 | H8: 0
B9: Tie | C9: 2
B10: Losers | C10: 0 | E10: Golfers
E11: Joey | F11: Cal | G11: Brandt | H11: Bryan
E12: Brandt | F12: GT | G12: Jared | H12: Stefan
E13: Joe | F13: Bird | G13: Hunter

Sheet Example Leaderboard
B2: Example Leaderboard | G2: Bragging Rights
B3: Pos. | C3: Golfer | D3: Points | E3: Behind | G3: Golfer | H3: Match Wins | I3: No Shows | J3: Lowest Score
B4: 1 | C4: Joey | D4: =SUMIF('Example Weekly Point Data'!$D:$D, C4, 'Example Weekly Point Data'!$Q:$Q) -> 39 | E4: 0 | G4: =C4 -> Joey | H4: =COUNTIFS('Example Weekly Point Data'!G:G,"Won",'Example Weekly Point Data'!D:D,G4) -> 1 | I4: =COUNTIFS('Example Weekly Point Data'!F:F,"No",'Example Weekly Point Data'!D:D,G4) -> 0 | J4: =MINIFS('Example Weekly Point Data'!I:I,'Example Weekly Point Data'!D:D,G4) -> 43
B5: 2 | C5: Cal | D5: =SUMIF('Example Weekly Point Data'!$D:$D, C5, 'Example Weekly Point Data'!$Q:$Q) -> 37 | E5: =D5-$D$4 -> -2 | G5: =C5 -> Cal | H5: =COUNTIFS('Example Weekly Point Data'!G:G,"Won",'Example Weekly Point Data'!D:D,G5) -> 1 | I5: =COUNTIFS('Example Weekly Point Data'!F:F,"No",'Example Weekly Point Data'!D:D,G5) -> 0 | J5: =MINIFS('Example Weekly Point Data'!I:I,'Example Weekly Point Data'!D:D,G5) -> 47
B6: 3 | C6: Brandt | D6: =SUMIF('Example Weekly Point Data'!$D:$D, C6, 'Example Weekly Point Data'!$Q:$Q) -> 34 | E6: =D6-$D$4 -> -5 | G6: =C6 -> Brandt | H6: =COUNTIFS('Example Weekly Point Data'!G:G,"Won",'Example Weekly Point Data'!D:D,G6) -> 0 | I6: =COUNTIFS('Example Weekly Point Data'!F:F,"No",'Example Weekly Point Data'!D:D,G6) -> 0 | J6: =MINIFS('Example Weekly Point Data'!I:I,'Example Weekly Point Data'!D:D,G6) -> 43
B7: 4 | C7: GT | D7: =SUMIF('Example Weekly Point Data'!$D:$D, C7, 'Example Weekly Point Data'!$Q:$Q) -> 28 | E7: =D7-$D$4 -> -11 | G7: =C7 -> GT | H7: =COUNTIFS('Example Weekly Point Data'!G:G,"Won",'Example Weekly Point Data'!D:D,G7) -> 0 | I7: =COUNTIFS('Example Weekly Point Data'!F:F,"No",'Example Weekly Point Data'!D:D,G7) -> 0 | J7: =MINIFS('Example Weekly Point Data'!I:I,'Example Weekly Point Data'!D:D,G7) -> 46
B8: 5 | C8: Bryan | D8: =SUMIF('Example Weekly Point Data'!$D:$D, C8, 'Example Weekly Point Data'!$Q:$Q) -> 23 | E8: =D8-$D$4 -> -16 | G8: =C8 -> Bryan | H8: =COUNTIFS('Example Weekly Point Data'!G:G,"Won",'Example Weekly Point Data'!D:D,G8) -> 1 | I8: =COUNTIFS('Example Weekly Point Data'!F:F,"No",'Example Weekly Point Data'!D:D,G8) -> 0 | J8: =MINIFS('Example Weekly Point Data'!I:I,'Example Weekly Point Data'!D:D,G8) -> 49
B9: 6 | C9: Zach | D9: =SUMIF('Example Weekly Point Data'!$D:$D, C9, 'Example Weekly Point Data'!$Q:$Q) -> 22 | E9: =D9-$D$4 -> -17 | G9: =C9 -> Zach | H9: =COUNTIFS('Example Weekly Point Data'!G:G,"Won",'Example Weekly Point Data'!D:D,G9) -> 0 | I9: =COUNTIFS('Example Weekly Point Data'!F:F,"No",'Example Weekly Point Data'!D:D,G9) -> 0 | J9: =MINIFS('Example Weekly Point Data'!I:I,'Example Weekly Point Data'!D:D,G9) -> 48
B10: 7 | C10: Joe | D10: =SUMIF('Example Weekly Point Data'!$D:$D, C10, 'Example Weekly Point Data'!$Q:$Q) -> 21 | E10: =D10-$D$4 -> -18 | G10: =C10 -> Joe | H10: =COUNTIFS('Example Weekly Point Data'!G:G,"Won",'Example Weekly Point Data'!D:D,G10) -> 1 | I10: =COUNTIFS('Example Weekly Point Data'!F:F,"No",'Example Weekly Point Data'!D:D,G10) -> 0 | J10: =MINIFS('Example Weekly Point Data'!I:I,'Example Weekly Point Data'!D:D,G10) -> 48
B11: 9 | C11: Jared | D11: =SUMIF('Example Weekly Point Data'!$D:$D, C11, 'Example Weekly Point Data'!$Q:$Q) -> 15 | E11: =D11-$D$4 -> -24 | G11: =C11 -> Jared | H11: =COUNTIFS('Example Weekly Point Data'!G:G,"Won",'Example Weekly Point Data'!D:D,G11) -> 1 | I11: =COUNTIFS('Example Weekly Point Data'!F:F,"No",'Example Weekly Point Data'!D:D,G11) -> 1 | J11: =MINIFS('Example Weekly Point Data'!I:I,'Example Weekly Point Data'!D:D,G11) -> 52
B12: 9 | C12: Bird | D12: =SUMIF('Example Weekly Point Data'!$D:$D, C12, 'Example Weekly Point Data'!$Q:$Q) -> 14 | E12: =D12-$D$4 -> -25 | G12: =C12 -> Bird | H12: =COUNTIFS('Example Weekly Point Data'!G:G,"Won",'Example Weekly Point Data'!D:D,G12) -> 0 | I12: =COUNTIFS('Example Weekly Point Data'!F:F,"No",'Example Weekly Point Data'!D:D,G12) -> 0 | J12: =MINIFS('Example Weekly Point Data'!I:I,'Example Weekly Point Data'!D:D,G12) -> 50
B13: 10 | C13: Hunter | D13: =SUMIF('Example Weekly Point Data'!$D:$D, C13, 'Example Weekly Point Data'!$Q:$Q) -> 0 | E13: =D13-$D$4 -> -39 | G13: =C13 -> Hunter | H13: =COUNTIFS('Example Weekly Point Data'!G:G,"Won",'Example Weekly Point Data'!D:D,G13) -> 0 | I13: =COUNTIFS('Example Weekly Point Data'!F:F,"No",'Example Weekly Point Data'!D:D,G13) -> 0 | J13: =MINIFS('Example Weekly Point Data'!I:I,'Example Weekly Point Data'!D:D,G13) -> 0
B14: 11 | C14: Stefan | D14: =SUMIF('Example Weekly Point Data'!$D:$D, C14, 'Example Weekly Point Data'!$Q:$Q) -> 0 | E14: =D14-$D$4 -> -39 | G14: =C14 -> Stefan | H14: =COUNTIFS('Example Weekly Point Data'!G:G,"Won",'Example Weekly Point Data'!D:D,G14) -> 0 | I14: =COUNTIFS('Example Weekly Point Data'!F:F,"No",'Example Weekly Point Data'!D:D,G14) -> 0 | J14: =MINIFS('Example Weekly Point Data'!I:I,'Example Weekly Point Data'!D:D,G14) -> 0
B15: 12 | D15: =SUMIF('Example Weekly Point Data'!$D:$D, C15, 'Example Weekly Point Data'!$Q:$Q) -> 0 | E15: =D15-$D$4 -> -39 | G15: =C15

Sheet Example Weekly Point Data
A1: Weekly Details | E1: Match Details | L1: Point Details | Q1: Total
A2: Week | B2: Date | C2: Course | D2: Golfer | E2: Partner | F2: Showed | G2: Match Result | H2: Handi cap | I2: Gross Score | J2: Net Score | K2: Putts | L2: Showing Up Points | M2: Match Points | N2: Gross Points | O2: Net Points | P2: Putt Points | Q2: Points
A3: ExW1 | B3: 46096 | C3: Willis Case | D3: Bird | E3: Brandt | F3: Yes | G3: Tied | H3: 17.9 | I3: 50 | J3: =I3-ROUNDUP(H3/2,0) -> 41 | K3: 19 | L3: =IFS(F3="Yes",3,F3="No",0) -> 3 | M3: =IFS(G3="Tied",2,G3="Won",5,G3="Lost",0) -> 2 | N3: 0 | O3: 1 | P3: 2 | Q3: =SUM(L3:P3) -> 8
A4: ExW1 | B4: 46096 | C4: Willis Case | D4: Brandt | E4: Bird | F4: Yes | G4: Tied | H4: 9.1 | I4: 43 | J4: =I4-ROUNDUP(H4/2,0) -> 38 | K4: 18 | L4: =IFS(F4="Yes",3,F4="No",0) -> 3 | M4: =IFS(G4="Tied",2,G4="Won",5,G4="Lost",0) -> 2 | N4: 6 | O4: 3 | P4: 3 | Q4: =SUM(L4:P4) -> 17
A5: ExW1 | B5: 46096 | C5: Willis Case | D5: Bryan | E5: GT | F5: Yes | G5: Lost | H5: 19.1 | I5: 49 | J5: =I5-ROUNDUP(H5/2,0) -> 39 | K5: 18 | L5: =IFS(F5="Yes",3,F5="No",0) -> 3 | M5: =IFS(G5="Tied",2,G5="Won",5,G5="Lost",0) -> 0 | N5: 1 | O5: 2 | P5: 3 | Q5: =SUM(L5:P5) -> 9
A6: ExW1 | B6: 46096 | C6: Willis Case | D6: Cal | E6: Zach | F6: Yes | G6: Tied | H6: 19.1 | I6: 47 | J6: =I6-ROUNDUP(H6/2,0) -> 37 | K6: 16 | L6: =IFS(F6="Yes",3,F6="No",0) -> 3 | M6: =IFS(G6="Tied",2,G6="Won",5,G6="Lost",0) -> 2 | N6: 3 | O6: 4 | P6: 5 | Q6: =SUM(L6:P6) -> 17
A7: ExW1 | B7: 46096 | C7: Willis Case | D7: GT | E7: Bryan | F7: Yes | G7: Lost | H7: 12.1 | I7: 46 | J7: =I7-ROUNDUP(H7/2,0) -> 39 | K7: 17 | L7: =IFS(F7="Yes",3,F7="No",0) -> 3 | M7: =IFS(G7="Tied",2,G7="Won",5,G7="Lost",0) -> 0 | N7: 4 | O7: 2 | P7: 4 | Q7: =SUM(L7:P7) -> 13
A8: ExW1 | B8: 46096 | C8: Willis Case | D8: Jared | E8: Joey | F8: Yes | G8: Won | H8: 28.5 | I8: 52 | J8: =I8-ROUNDUP(H8/2,0) -> 37 | K8: 18 | L8: =IFS(F8="Yes",3,F8="No",0) -> 3 | M8: =IFS(G8="Tied",2,G8="Won",5,G8="Lost",0) -> 5 | N8: 0 | O8: 4 | P8: 3 | Q8: =SUM(L8:P8) -> 15
A9: ExW1 | B9: 46096 | C9: Willis Case | D9: Joe | E9: Handicap | F9: Yes | G9: Won | H9: 17.9 | I9: 48 | J9: =I9-ROUNDUP(H9/2,0) -> 39 | K9: 21 | L9: =IFS(F9="Yes",3,F9="No",0) -> 3 | M9: =IFS(G9="Tied",2,G9="Won",5,G9="Lost",0) -> 5 | N9: 2 | O9: 2 | P9: 0 | Q9: =SUM(L9:P9) -> 12
A10: ExW1 | B10: 46096 | C10: Willis Case | D10: Joey | E10: Jared | F10: Yes | G10: Won | H10: 12.3 | I10: 43 | J10: =I10-ROUNDUP(H10/2,0) -> 36 | K10: 19 | L10: =IFS(F10="Yes",3,F10="No",0) -> 3 | M10: =IFS(G10="Tied",2,G10="Won",5,G10="Lost",0) -> 5 | N10: 6 | O10: 6 | P10: 2 | Q10: =SUM(L10:P10) -> 22
A11: ExW1 | B11: 46096 | C11: Willis Case | D11: Zach | E11: Cal | F11: Yes | G11: Tied | H11: 19.2 | I11: 48 | J11: =I11-ROUNDUP(H11/2,0) -> 38 | K11: 20 | L11: =IFS(F11="Yes",3,F11="No",0) -> 3 | M11: =IFS(G11="Tied",2,G11="Won",5,G11="Lost",0) -> 2 | N11: 2 | O11: 3 | P11: 1 | Q11: =SUM(L11:P11) -> 11
A12: ExW2 | B12: 46104 | C12: City Park | D12: Bird | E12: Cal | F12: Yes | G12: Lost | H12: 17.9 | I12: 50 | J12: =I12-ROUNDUP(H12/2,0) -> 41 | K12: 19 | L12: =IFS(F12="Yes",3,F12="No",0) -> 3 | M12: =IFS(G12="Tied",2,G12="Won",5,G12="Lost",0) -> 0 | N12: 0 | O12: 1 | P12: 2 | Q12: =SUM(L12:P12) -> 6
A13: ExW2 | B13: 46104 | C13: City Park | D13: Brandt | E13: Bryan | F13: Yes | G13: Tied | H13: 9.1 | I13: 43 | J13: =I13-ROUNDUP(H13/2,0) -> 38 | K13: 18 | L13: =IFS(F13="Yes",3,F13="No",0) -> 3 | M13: =IFS(G13="Tied",2,G13="Won",5,G13="Lost",0) -> 2 | N13: 6 | O13: 3 | P13: 3 | Q13: =SUM(L13:P13) -> 17
A14: ExW2 | B14: 46104 | C14: City Park | D14: Bryan | E14: Brandt | F14: Yes | G14: Won | H14: 19.1 | I14: 49 | J14: =I14-ROUNDUP(H14/2,0) -> 39 | K14: 18 | L14: =IFS(F14="Yes",3,F14="No",0) -> 3 | M14: =IFS(G14="Tied",2,G14="Won",5,G14="Lost",0) -> 5 | N14: 1 | O14: 2 | P14: 3 | Q14: =SUM(L14:P14) -> 14
... A16: ExW2 | B16: 46104 | C16: City Park | D16: GT | E16: Joey | F16: Yes | G16: Tied | H16: 12.1 | I16: 46 | J16: =I16-ROUNDUP(H16/2,0) -> 39 | K16: 17 | L16: =IFS(F16="Yes",3,F16="No",0) -> 3 | M16: =IFS(G16="Tied",2,G16="Won",5,G16="Lost",0) -> 2 | N16: 4 | O16: 2 | P16: 4 | Q16: =SUM(L16:P16) -> 15
A17: ExW2 | B17: 46104 | C17: City Park | D17: Jared | E17: n/a | F17: No | G17: Lost | H17: n/a | I17: n/a | J17: n/a | K17: n/a | L17: =IFS(F17="Yes",3,F17="No",0) -> 0 | M17: =IFS(G17="Tied",2,G17="Won",5,G17="Lost",0) -> 0 | N17: 0 | O17: 0 | P17: 0 | Q17: =SUM(L17:P17) -> 0
A18: ExW2 | B18: 46104 | C18: City Park | D18: Joe | E18: Zach | F18: Yes | G18: Tied | H18: 17.9 | I18: 48 | J18: =I18-ROUNDUP(H18/2,0) -> 39 | K18: 21 | L18: =IFS(F18="Yes",3,F18="No",0) -> 3 | M18: =IFS(G18="Tied",2,G18="Won",5,G18="Lost",0) -> 2 | N18: 2 | O18: 2 | P18: 0 | Q18: =SUM(L18:P18) -> 9
A19: ExW2 | B19: 46104 | C19: City Park | D19: Joey | E19: GT | F19: Yes | G19: Lost | H19: 12.3 | I19: 43 | J19: =I19-ROUNDUP(H19/2,0) -> 36 | K19: 19 | L19: =IFS(F19="Yes",3,F19="No",0) -> 3 | M19: =IFS(G19="Tied",2,G19="Won",5,G19="Lost",0) -> 0 | N19: 6 | O19: 6 | P19: 2 | Q19: =SUM(L19:P19) -> 17
A20: ExW2 | B20: 46104 | C20: City Park | D20: Zach | E20: Joey | F20: Yes | G20: Tied | H20: 19.2 | I20: 48 | J20: =I20-ROUNDUP(H20/2,0) -> 38 | K20: 20 | L20: =IFS(F20="Yes",3,F20="No",0) -> 3 | M20: =IFS(G20="Tied",2,G20="Won",5,G20="Lost",0) -> 2 | N20: 2 | O20: 3 | P20: 1 | Q20: =SUM(L20:P20) -> 11

Sheet Weekly Points
B1: Week | C1: Point Category | D1: Bryan | E1: Joey | F1: Cal | G1: Joe | H1: GT | I1: Jared | J1: Brandt | K1: Zach | L1: Bird
B3: Example Week | C3: Showing Up | D3: 3 | E3: 3 | F3: 3 | G3: 3 | H3: 3 | I3: 3 | J3: 3 | K3: 3 | L3: 3
C4: Match Play | D4: - | E4: 5 | F4: 2 | G4: 5 | H4: - | I4: 5 | J4: 2 | K4: 2 | L4: 2
C5: Gross Strokes | D5: 1 | E5: 6 | F5: 3 | G5: 2 | H5: 4 | I5: - | J5: 6 | K5: 2 | L5: -
C6: Net Strokes | D6: 2 | E6: 6 | F6: 4 | G6: 2 | H6: 2 | I6: 4 | J6: 3 | K6: 3 | L6: 1
C7: Putts | D7: 3 | E7: 3 | F7: 5 | G7: - | H7: 4 | I7: 2 | J7: 3 | K7: 1 | L7: 2
C8: Totals | D8: =SUM(D3:D7) -> 9 | E8: =SUM(E3:E7) -> 23 | F8: =SUM(F3:F7) -> 17 | G8: =SUM(G3:G7) -> 12 | H8: =SUM(H3:H7) -> 13 | I8: =SUM(I3:I7) -> 14 | J8: =SUM(J3:J7) -> 17 | K8: =SUM(K3:K7) -> 11 | L8: =SUM(L3:L7) -> 8
B10: Week 1 05/05 | C10: Showing Up
C11: Match Play
C12: Gross Strokes
C13: Net Strokes
C14: Putts
C15: Totals

Sheet Stroke & Putt History
B1: Week | C1: Detail | D1: Bryan | E1: Joey | F1: Cal | G1: Joe | H1: GT | I1: Jared | J1: Brandt | K1: Zach | L1: Bird
B3: Example Week | C3: Handicap | D3: 19.1 | E3: 12.3 | F3: 19.1 | G3: 17.9 | H3: 12.1 | I3: 28.5 | J3: 9.1 | K3: 19.2 | L3: 17.9
C4: Gross Score | D4: 49 | E4: 43 | F4: 47 | G4: 48 | H4: 46 | I4: 52 | J4: 43 | K4: 48 | L4: 50
C5: Net Score | D5: =D4-ROUNDUP((D3/2),0) -> 39 | E5: =E4-ROUNDUP((E3/2),0) -> 36 | F5: =F4-ROUNDUP((F3/2),0) -> 37 | G5: =G4-ROUNDUP((G3/2),0) -> 39 | H5: =H4-ROUNDUP((H3/2),0) -> 39 | I5: =I4-ROUNDUP((I3/2),0) -> 37 | J5: =J4-ROUNDUP((J3/2),0) -> 38 | K5: =K4-ROUNDUP((K3/2),0) -> 38 | L5: =L4-ROUNDUP((L3/2),0) -> 41
C6: Putts | D6: 18 | E6: 18 | F6: 16 | G6: 21 | H6: 17 | I6: 19 | J6: 18 | K6: 20 | L6: 19
B8: Week 1 05/05 | C8: Handicap
C9: Gross Score
C10: Net Score
C11: Putts
